Workbook

Sheet ConceptSet
A1: id | B1: code | C1: name | D1: type | E1: regex | F1: schema_definition | G1: schema_uri | H1: description
A2: 0198ef6d-8543-90a8-a647-ae05912c77ba | B2: NOMINAL_1 | C2: Nominal_1 | D2: NOMINAL | H2: CATEGORY1_1, CATEGORY1_2, CATEGORY1_3
A3: 0198ef6d-8543-2a99-b3be-b0d2583cb604 | B3: NOMINAL_2 | C3: Nominal_2 | D3: NOMINAL | H3: CATEGORY2_1, CATEGORY2_2, CATEGORY2_3
A4: 0198ef6d-8543-b279-03a6-da9684b42b08 | B4: ORDINAL_1 | C4: Ordinal_1 | D4: ORDINAL | H4: RANK1_1, RANK1_2, RANK1_3
A5: 0198ef6d-8543-d076-3da0-dd48921087f9 | B5: ORDINAL_2 | C5: Ordinal_2 | D5: ORDINAL | H5: RANK2_1, RANK2_2, RANK2_3
A6: 0198ef6d-8543-020d-44c5-53e813a46714 | B6: AGE_CATEGORY_1 | C6: Age in years, intervals 0, 5, 15, 25, 45, 65 | D6: INTERVAL | H6: Age in years, intervals 0, 5, 15, 25, 45, 65
A7: 0198ef6d-8543-2a37-be54-7f7d24e1ed1d | B7: AGE_CATEGORY_2 | C7: Age in years, intervals 0, 5, 19, 65 | D7: INTERVAL | H7: Age in years, intervals 0, 5, 19, 65
A8: 0198ef6d-8543-f668-cedc-b78f8e3bc412 | B8: AGE_CATEGORY_3 | C8: Age in years, intervals 0, 15, 25, 35, 45 | D8: INTERVAL | H8: Age in years, intervals 0, 15, 25, 35, 45
A9: 0198ef6d-8543-2673-a691-fe8584d0695e | B9: AGE_CATEGORY_4 | C9: Age in years, intervals 0, 1, 5, 15, 20, 25, 35, 45, 55, 65 | D9: INTERVAL | H9: Age in years, intervals 0, 1, 5, 15, 20, 25, 35, 45, 55, 65
A10: 0198ef6d-8543-cb6b-0c98-c2a7e640e10d | B10: AGE_CATEGORY_5 | C10: Age in months, intervals 0, 1, 2, 3 | D10: INTERVAL | H10: Age in months, intervals 0, 1, 2, 3
A11: 0198ef6d-8543-a151-ab47-0394a80e2a05 | B11: REGULAR_LANGUAGE_1 | C11: Regex_1 | D11: REGULAR_LANGUAGE | E11: A\d+ | H11: A\d+
A12: 0198ef6d-8543-6df8-9098-78280604c758 | B12: REGULAR_LANGUAGE_2 | C12: Regex_2 | D12: REGULAR_LANGUAGE | E12: B\d+ | H12: B\d+

Sheet Concept
A1: id | B1: code | C1: name | D1: description | E1: rank | F1: props | G1: dm.lb | H1: dm.ub | I1: dm.concept_set_code | J1: concept_set_id | K1: dm.key.id | L1: dm.key.abbreviation | M1: dm.key.name
A2: 0198ef6d-8543-1558-187c-47880d4b485e | B2: CATEGORY1 | C2: Category1_1 | F2: {} | I2: =INDEX(ConceptSet!$B:$B,MATCH($J2,ConceptSet!$A:$A,0)) -> NOMINAL_1 | J2: 0198ef6d-8543-90a8-a647-ae05912c77ba | K2: =LOWER($J2)&"|"&LOWER($A2) -> 0198ef6d-8543-90a8-a647-ae05912c77ba|0198ef6d-8543-1558-187c-47880d4b485e | L2: =LOWER($J2)&"|"&LOWER($B2) -> 0198ef6d-8543-90a8-a647-ae05912c77ba|category1 | M2: =LOWER($J2)&"|"&LOWER($C2) -> 0198ef6d-8543-90a8-a647-ae05912c77ba|category1_1
A3: 0198ef6d-8543-022e-af76-07950e3be6d8 | B3: CATEGORY2 | C3: Category1_2 | F3: {} | I3: =INDEX(ConceptSet!$B:$B,MATCH($J3,ConceptSet!$A:$A,0)) -> NOMINAL_1 | J3: 0198ef6d-8543-90a8-a647-ae05912c77ba | K3: =LOWER($J3)&"|"&LOWER($A3) -> 0198ef6d-8543-90a8-a647-ae05912c77ba|0198ef6d-8543-022e-af76-07950e3be6d8 | L3: =LOWER($J3)&"|"&LOWER($B3) -> 0198ef6d-8543-90a8-a647-ae05912c77ba|category2 | M3: =LOWER($J3)&"|"&LOWER($C3) -> 0198ef6d-8543-90a8-a647-ae05912c77ba|category1_2
A4: 0198ef6d-8543-e759-11f0-adca304123d1 | B4: CATEGORY3 | C4: Category1_3 | F4: {} | I4: =INDEX(ConceptSet!$B:$B,MATCH($J4,ConceptSet!$A:$A,0)) -> NOMINAL_1 | J4: 0198ef6d-8543-90a8-a647-ae05912c77ba | K4: =LOWER($J4)&"|"&LOWER($A4) -> 0198ef6d-8543-90a8-a647-ae05912c77ba|0198ef6d-8543-e759-11f0-adca304123d1 | L4: =LOWER($J4)&"|"&LOWER($B4) -> 0198ef6d-8543-90a8-a647-ae05912c77ba|category3 | M4: =LOWER($J4)&"|"&LOWER($C4) -> 0198ef6d-8543-90a8-a647-ae05912c77ba|category1_3
A5: 0198ef6d-8543-6ac9-4915-b0f74393baa3 | B5: CATEGORY1 | C5: Category2_1 | F5: {} | I5: =INDEX(ConceptSet!$B:$B,MATCH($J5,ConceptSet!$A:$A,0)) -> NOMINAL_2 | J5: 0198ef6d-8543-2a99-b3be-b0d2583cb604 | K5: =LOWER($J5)&"|"&LOWER($A5) -> 0198ef6d-8543-2a99-b3be-b0d2583cb604|0198ef6d-8543-6ac9-4915-b0f74393baa3 | L5: =LOWER($J5)&"|"&LOWER($B5) -> 0198ef6d-8543-2a99-b3be-b0d2583cb604|category1 | M5: =LOWER($J5)&"|"&LOWER($C5) -> 0198ef6d-8543-2a99-b3be-b0d2583cb604|category2_1
A6: 0198ef6d-8543-d8eb-6c3e-2b68e40942f8 | B6: CATEGORY2 | C6: Category2_2 | F6: {} | I6: =INDEX(ConceptSet!$B:$B,MATCH($J6,ConceptSet!$A:$A,0)) -> NOMINAL_2 | J6: 0198ef6d-8543-2a99-b3be-b0d2583cb604 | K6: =LOWER($J6)&"|"&LOWER($A6) -> 0198ef6d-8543-2a99-b3be-b0d2583cb604|0198ef6d-8543-d8eb-6c3e-2b68e40942f8 | L6: =LOWER($J6)&"|"&LOWER($B6) -> 0198ef6d-8543-2a99-b3be-b0d2583cb604|category2 | M6: =LOWER($J6)&"|"&LOWER($C6) -> 0198ef6d-8543-2a99-b3be-b0d2583cb604|category2_2
A7: 0198ef6d-8543-2764-1452-6fe25c191511 | B7: CATEGORY3 | C7: Category2_3 | F7: {} | I7: =INDEX(ConceptSet!$B:$B,MATCH($J7,ConceptSet!$A:$A,0)) -> NOMINAL_2 | J7: 0198ef6d-8543-2a99-b3be-b0d2583cb604 | K7: =LOWER($J7)&"|"&LOWER($A7) -> 0198ef6d-8543-2a99-b3be-b0d2583cb604|0198ef6d-8543-2764-1452-6fe25c191511 | L7: =LOWER($J7)&"|"&LOWER($B7) -> 0198ef6d-8543-2a99-b3be-b0d2583cb604|category3 | M7: =LOWER($J7)&"|"&LOWER($C7) -> 0198ef6d-8543-2a99-b3be-b0d2583cb604|category2_3
A8: 0198ef6d-8543-73c8-d3af-92aa66e44b8c | B8: RANK1 | C8: Rank1_1 | E8: 1 | F8: {} | I8: =INDEX(ConceptSet!$B:$B,MATCH($J8,ConceptSet!$A:$A,0)) -> ORDINAL_1 | J8: 0198ef6d-8543-b279-03a6-da9684b42b08 | K8: =LOWER($J8)&"|"&LOWER($A8) -> 0198ef6d-8543-b279-03a6-da9684b42b08|0198ef6d-8543-73c8-d3af-92aa66e44b8c | L8: =LOWER($J8)&"|"&LOWER($B8) -> 0198ef6d-8543-b279-03a6-da9684b42b08|rank1 | M8: =LOWER($J8)&"|"&LOWER($C8) -> 0198ef6d-8543-b279-03a6-da9684b42b08|rank1_1
A9: 0198ef6d-8543-7395-2023-95bfee798f65 | B9: RANK2 | C9: Rank1_2 | E9: 2 | F9: {} | I9: =INDEX(ConceptSet!$B:$B,MATCH($J9,ConceptSet!$A:$A,0)) -> ORDINAL_1 | J9: 0198ef6d-8543-b279-03a6-da9684b42b08 | K9: =LOWER($J9)&"|"&LOWER($A9) -> 0198ef6d-8543-b279-03a6-da9684b42b08|0198ef6d-8543-7395-2023-95bfee798f65 | L9: =LOWER($J9)&"|"&LOWER($B9) -> 0198ef6d-8543-b279-03a6-da9684b42b08|rank2 | M9: =LOWER($J9)&"|"&LOWER($C9) -> 0198ef6d-8543-b279-03a6-da9684b42b08|rank1_2
A10: 0198ef6d-8543-ef67-b7ee-fa35926c01fd | B10: RANK3 | C10: Rank1_3 | E10: 3 | F10: {} | I10: =INDEX(ConceptSet!$B:$B,MATCH($J10,ConceptSet!$A:$A,0)) -> ORDINAL_1 | J10: 0198ef6d-8543-b279-03a6-da9684b42b08 | K10: =LOWER($J10)&"|"&LOWER($A10) -> 0198ef6d-8543-b279-03a6-da9684b42b08|0198ef6d-8543-ef67-b7ee-fa35926c01fd | L10: =LOWER($J10)&"|"&LOWER($B10) -> 0198ef6d-8543-b279-03a6-da9684b42b08|rank3 | M10: =LOWER($J10)&"|"&LOWER($C10) -> 0198ef6d-8543-b279-03a6-da9684b42b08|rank1_3
A11: 0198ef6d-8543-1842-1575-0be542168d82 | B11: RANK1 | C11: Rank2_1 | E11: 1 | F11: {} | I11: =INDEX(ConceptSet!$B:$B,MATCH($J11,ConceptSet!$A:$A,0)) -> ORDINAL_2 | J11: 0198ef6d-8543-d076-3da0-dd48921087f9 | K11: =LOWER($J11)&"|"&LOWER($A11) -> 0198ef6d-8543-d076-3da0-dd48921087f9|0198ef6d-8543-1842-1575-0be542168d82 | L11: =LOWER($J11)&"|"&LOWER($B11) -> 0198ef6d-8543-d076-3da0-dd48921087f9|rank1 | M11: =LOWER($J11)&"|"&LOWER($C11) -> 0198ef6d-8543-d076-3da0-dd48921087f9|rank2_1
A12: 0198ef6d-8543-db07-f368-c8dd91590021 | B12: RANK2 | C12: Rank2_2 | E12: 2 | F12: {} | I12: =INDEX(ConceptSet!$B:$B,MATCH($J12,ConceptSet!$A:$A,0)) -> ORDINAL_2 | J12: 0198ef6d-8543-d076-3da0-dd48921087f9 | K12: =LOWER($J12)&"|"&LOWER($A12) -> 0198ef6d-8543-d076-3da0-dd48921087f9|0198ef6d-8543-db07-f368-c8dd91590021 | L12: =LOWER($J12)&"|"&LOWER($B12) -> 0198ef6d-8543-d076-3da0-dd48921087f9|rank2 | M12: =LOWER($J12)&"|"&LOWER($C12) -> 0198ef6d-8543-d076-3da0-dd48921087f9|rank2_2
A13: 0198ef6d-8543-403c-ce3e-33a4efc54a25 | B13: RANK3 | C13: Rank2_3 | E13: 3 | F13: {} | I13: =INDEX(ConceptSet!$B:$B,MATCH($J13,ConceptSet!$A:$A,0)) -> ORDINAL_2 | J13: 0198ef6d-8543-d076-3da0-dd48921087f9 | K13: =LOWER($J13)&"|"&LOWER($A13) -> 0198ef6d-8543-d076-3da0-dd48921087f9|0198ef6d-8543-403c-ce3e-33a4efc54a25 | L13: =LOWER($J13)&"|"&LOWER($B13) -> 0198ef6d-8543-d076-3da0-dd48921087f9|rank3 | M13: =LOWER($J13)&"|"&LOWER($C13) -> 0198ef6d-8543-d076-3da0-dd48921087f9|rank2_3
A14: 0198ef6d-8543-9d0a-baf1-e5c51942de4e | B14: =IF($G14=$H14-1,$G14&"",$G14&IF($H14=125,"+","-"&$H14-1)) -> 5-14 | C14: ="Age in years, ["&$G14&", "&$H14&"[" -> Age in years, [5, 15[ | E14: 1 | F14: ="{""lb"":"&$G14&",""lb_in"":true,""ub"":"&$H14&",""ub_in"":false,""unit"":""YEAR""}" -> {"lb":5,"lb_in":true,"ub":15,"ub_in":false,"unit":"YEAR"} | G14: 5 | H14: 15 | I14: =INDEX(ConceptSet!$B:$B,MATCH($J14,ConceptSet!$A:$A,0)) -> AGE_CATEGORY_1 | J14: 0198ef6d-8543-020d-44c5-53e813a46714 | K14: =LOWER($J14)&"|"&LOWER($A14) -> 0198ef6d-8543-020d-44c5-53e813a46714|0198ef6d-8543-9d0a-baf1-e5c51942de4e | L14: =LOWER($J14)&"|"&LOWER($B14) -> 0198ef6d-8543-020d-44c5-53e813a46714|5-14 | M14: =LOWER($J14)&"|"&LOWER($C14) -> 0198ef6d-8543-020d-44c5-53e813a46714|age in years, [5, 15[
A15: 0198ef6d-8543-d03b-b9f4-f460fae89f04 | B15: =IF($G15=$H15-1,$G15&"",$G15&IF($H15=125,"+","-"&$H15-1)) -> 15-24 | C15: ="Age in years, ["&$G15&", "&$H15&"[" -> Age in years, [15, 25[ | E15: 2 | F15: ="{""lb"":"&$G15&",""lb_in"":true,""ub"":"&$H15&",""ub_in"":false,""unit"":""YEAR""}" -> {"lb":15,"lb_in":true,"ub":25,"ub_in":false,"unit":"YEAR"} | G15: 15 | H15: 25 | I15: =INDEX(ConceptSet!$B:$B,MATCH($J15,ConceptSet!$A:$A,0)) -> AGE_CATEGORY_1 | J15: 0198ef6d-8543-020d-44c5-53e813a46714 | K15: =LOWER($J15)&"|"&LOWER($A15) -> 0198ef6d-8543-020d-44c5-53e813a46714|0198ef6d-8543-d03b-b9f4-f460fae89f04 | L15: =LOWER($J15)&"|"&LOWER($B15) -> 0198ef6d-8543-020d-44c5-53e813a46714|15-24 | M15: =LOWER($J15)&"|"&LOWER($C15) -> 0198ef6d-8543-020d-44c5-53e813a46714|age in years, [15, 25[
A16: 0198ef6d-8543-e70f-7b7c-8e2af8fe9e2d | B16: =IF($G16=$H16-1,$G16&"",$G16&IF($H16=125,"+","-"&$H16-1)) -> 25-44 | C16: ="Age in years, ["&$G16&", "&$H16&"[" -> Age in years, [25, 45[ | E16: 3 | F16: ="{""lb"":"&$G16&",""lb_in"":true,""ub"":"&$H16&",""ub_in"":false,""unit"":""YEAR""}" -> {"lb":25,"lb_in":true,"ub":45,"ub_in":false,"unit":"YEAR"} | G16: 25 | H16: 45 | I16: =INDEX(ConceptSet!$B:$B,MATCH($J16,ConceptSet!$A:$A,0)) -> AGE_CATEGORY_1 | J16: 0198ef6d-8543-020d-44c5-53e813a46714 | K16: =LOWER($J16)&"|"&LOWER($A16) -> 0198ef6d-8543-020d-44c5-53e813a46714|0198ef6d-8543-e70f-7b7c-8e2af8fe9e2d | L16: =LOWER($J16)&"|"&LOWER($B16) -> 0198ef6d-8543-020d-44c5-53e813a46714|25-44 | M16: =LOWER($J16)&"|"&LOWER($C16) -> 0198ef6d-8543-020d-44c5-53e813a46714|age in years, [25, 45[
A17: 0198ef6d-8543-8304-54a7-34542a0a9c33 | B17: =IF($G17=$H17-1,$G17&"",$G17&IF($H17=125,"+","-"&$H17-1)) -> 45-64 | C17: ="Age in years, ["&$G17&", "&$H17&"[" -> Age in years, [45, 65[ | E17: 4 | F17: ="{""lb"":"&$G17&",""lb_in"":true,""ub"":"&$H17&",""ub_in"":false,""unit"":""YEAR""}" -> {"lb":45,"lb_in":true,"ub":65,"ub_in":false,"unit":"YEAR"} | G17: 45 | H17: 65 | I17: =INDEX(ConceptSet!$B:$B,MATCH($J17,ConceptSet!$A:$A,0)) -> AGE_CATEGORY_1 | J17: 0198ef6d-8543-020d-44c5-53e813a46714 | K17: =LOWER($J17)&"|"&LOWER($A17) -> 0198ef6d-8543-020d-44c5-53e813a46714|0198ef6d-8543-8304-54a7-34542a0a9c33 | L17: =LOWER($J17)&"|"&LOWER($B17) -> 0198ef6d-8543-020d-44c5-53e813a46714|45-64 | M17: =LOWER($J17)&"|"&LOWER($C17) -> 0198ef6d-8543-020d-44c5-53e813a46714|age in years, [45, 65[
A18: 0198ef6d-8543-c436-8749-ad1b2a75b4ba | B18: =IF($G18=$H18-1,$G18&"",$G18&IF($H18=125,"+","-"&$H18-1)) -> 65+ | C18: ="Age in years, ["&$G18&", "&$H18&"[" -> Age in years, [65, 125[ | E18: 5 | F18: ="{""lb"":"&$G18&",""lb_in"":true,""ub"":"&$H18&",""ub_in"":false,""unit"":""YEAR""}" -> {"lb":65,"lb_in":true,"ub":125,"ub_in":false,"unit":"YEAR"} | G18: 65 | H18: 125 | I18: =INDEX(ConceptSet!$B:$B,MATCH($J18,ConceptSet!$A:$A,0)) -> AGE_CATEGORY_1 | J18: 0198ef6d-8543-020d-44c5-53e813a46714 | K18: =LOWER($J18)&"|"&LOWER($A18) -> 0198ef6d-8543-020d-44c5-53e813a46714|0198ef6d-8543-c436-8749-ad1b2a75b4ba | L18: =LOWER($J18)&"|"&LOWER($B18) -> 0198ef6d-8543-020d-44c5-53e813a46714|65+ | M18: =LOWER($J18)&"|"&LOWER($C18) -> 0198ef6d-8543-020d-44c5-53e813a46714|age in years, [65, 125[
A19: 0198ef6d-8543-893c-c5e2-73c38bec9ac6 | B19: =IF($G19=$H19-1,$G19&"",$G19&IF($H19=125,"+","-"&$H19-1)) -> 5-18 | C19: ="Age in years, ["&$G19&", "&$H19&"[" -> Age in years, [5, 19[ | E19: 1 | F19: ="{""lb"":"&$G19&",""lb_in"":true,""ub"":"&$H19&",""ub_in"":false,""unit"":""YEAR""}" -> {"lb":5,"lb_in":true,"ub":19,"ub_in":false,"unit":"YEAR"} | G19: 5 | H19: 19 | I19: =INDEX(ConceptSet!$B:$B,MATCH($J19,ConceptSet!$A:$A,0)) -> AGE_CATEGORY_2 | J19: 0198ef6d-8543-2a37-be54-7f7d24e1ed1d | K19: =LOWER($J19)&"|"&LOWER($A19) -> 0198ef6d-8543-2a37-be54-7f7d24e1ed1d|0198ef6d-8543-893c-c5e2-73c38bec9ac6 | L19: =LOWER($J19)&"|"&LOWER($B19) -> 0198ef6d-8543-2a37-be54-7f7d24e1ed1d|5-18 | M19: =LOWER($J19)&"|"&LOWER($C19) -> 0198ef6d-8543-2a37-be54-7f7d24e1ed1d|age in years, [5, 19[
A20: 0198ef6d-8543-626b-c05d-de74547d3621 | B20: =IF($G20=$H20-1,$G20&"",$G20&IF($H20=125,"+","-"&$H20-1)) -> 19-64 | C20: ="Age in years, ["&$G20&", "&$H20&"[" -> Age in years, [19, 65[ | E20: 2 | F20: ="{""lb"":"&$G20&",""lb_in"":true,""ub"":"&$H20&",""ub_in"":false,""unit"":""YEAR""}" -> {"lb":19,"lb_in":true,"ub":65,"ub_in":false,"unit":"YEAR"} | G20: 19 | H20: 65 | I20: =INDEX(ConceptSet!$B:$B,MATCH($J20,ConceptSet!$A:$A,0)) -> AGE_CATEGORY_2 | J20: 0198ef6d-8543-2a37-be54-7f7d24e1ed1d | K20: =LOWER($J20)&"|"&LOWER($A20) -> 0198ef6d-8543-2a37-be54-7f7d24e1ed1d|0198ef6d-8543-626b-c05d-de74547d3621 | L20: =LOWER($J20)&"|"&LOWER($B20) -> 0198ef6d-8543-2a37-be54-7f7d24e1ed1d|19-64 | M20: =LOWER($J20)&"|"&LOWER($C20) -> 0198ef6d-8543-2a37-be54-7f7d24e1ed1d|age in years, [19, 65[
A21: 0198ef6d-8543-1ce7-83c8-e53fe4b7fb8e | B21: =IF($G21=$H21-1,$G21&"",$G21&IF($H21=125,"+","-"&$H21-1)) -> 0-14 | C21: ="Age in years, ["&$G21&", "&$H21&"[" -> Age in years, [0, 15[ | E21: 1 | F21: ="{""lb"":"&$G21&",""lb_in"":true,""ub"":"&$H21&",""ub_in"":false,""unit"":""YEAR""}" -> {"lb":0,"lb_in":true,"ub":15,"ub_in":false,"unit":"YEAR"} | G21: 0 | H21: 15 | I21: =INDEX(ConceptSet!$B:$B,MATCH($J21,ConceptSet!$A:$A,0)) -> AGE_CATEGORY_3 | J21: 0198ef6d-8543-f668-cedc-b78f8e3bc412 | K21: =LOWER($J21)&"|"&LOWER($A21) -> 0198ef6d-8543-f668-cedc-b78f8e3bc412|0198ef6d-8543-1ce7-83c8-e53fe4b7fb8e | L21: =LOWER($J21)&"|"&LOWER($B21) -> 0198ef6d-8543-f668-cedc-b78f8e3bc412|0-14 | M21: =LOWER($J21)&"|"&LOWER($C21) -> 0198ef6d-8543-f668-cedc-b78f8e3bc412|age in years, [0, 15[
A22: 0198ef6d-8543-773c-35de-7133eb350f0c | B22: =IF($G22=$H22-1,$G22&"",$G22&IF($H22=125,"+","-"&$H22-1)) -> 25-34 | C22: ="Age in years, ["&$G22&", "&$H22&"[" -> Age in years, [25, 35[ | E22: 2 | F22: ="{""lb"":"&$G22&",""lb_in"":true,""ub"":"&$H22&",""ub_in"":false,""unit"":""YEAR""}" -> {"lb":25,"lb_in":true,"ub":35,"ub_in":false,"unit":"YEAR"} | G22: 25 | H22: 35 | I22: =INDEX(ConceptSet!$B:$B,MATCH($J22,ConceptSet!$A:$A,0)) -> AGE_CATEGORY_3 | J22: 0198ef6d-8543-f668-cedc-b78f8e3bc412 | K22: =LOWER($J22)&"|"&LOWER($A22) -> 0198ef6d-8543-f668-cedc-b78f8e3bc412|0198ef6d-8543-773c-35de-7133eb350f0c | L22: =LOWER($J22)&"|"&LOWER($B22) -> 0198ef6d-8543-f668-cedc-b78f8e3bc412|25-34 | M22: =LOWER($J22)&"|"&LOWER($C22) -> 0198ef6d-8543-f668-cedc-b78f8e3bc412|age in years, [25, 35[
A23: 0198ef6d-8543-8382-74c3-3094271a22fd | B23: =IF($G23=$H23-1,$G23&"",$G23&IF($H23=125,"+","-"&$H23-1)) -> 35-44 | C23: ="Age in years, ["&$G23&", "&$H23&"[" -> Age in years, [35, 45[ | E23: 3 | F23: ="{""lb"":"&$G23&",""lb_in"":true,""ub"":"&$H23&",""ub_in"":false,""unit"":""YEAR""}" -> {"lb":35,"lb_in":true,"ub":45,"ub_in":false,"unit":"YEAR"} | G23: 35 | H23: 45 | I23: =INDEX(ConceptSet!$B:$B,MATCH($J23,ConceptSet!$A:$A,0)) -> AGE_CATEGORY_3 | J23: 0198ef6d-8543-f668-cedc-b78f8e3bc412 | K23: =LOWER($J23)&"|"&LOWER($A23) -> 0198ef6d-8543-f668-cedc-b78f8e3bc412|0198ef6d-8543-8382-74c3-3094271a22fd | L23: =LOWER($J23)&"|"&LOWER($B23) -> 0198ef6d-8543-f668-cedc-b78f8e3bc412|35-44 | M23: =LOWER($J23)&"|"&LOWER($C23) -> 0198ef6d-8543-f668-cedc-b78f8e3bc412|age in years, [35, 45[
A24: 0198ef6d-8543-9cc1-eca7-e072c2b8acae | B24: =IF($G24=$H24-1,$G24&"",$G24&IF($H24=125,"+","-"&$H24-1)) -> 45+ | C24: ="Age in years, ["&$G24&", "&$H24&"[" -> Age in years, [45, 125[ | E24: 4 | F24: ="{""lb"":"&$G24&",""lb_in"":true,""ub"":"&$H24&",""ub_in"":false,""unit"":""YEAR""}" -> {"lb":45,"lb_in":true,"ub":125,"ub_in":false,"unit":"YEAR"} | G24: 45 | H24: 125 | I24: =INDEX(ConceptSet!$B:$B,MATCH($J24,ConceptSet!$A:$A,0)) -> AGE_CATEGORY_3 | J24: 0198ef6d-8543-f668-cedc-b78f8e3bc412 | K24: =LOWER($J24)&"|"&LOWER($A24) -> 0198ef6d-8543-f668-cedc-b78f8e3bc412|0198ef6d-8543-9cc1-eca7-e072c2b8acae | L24: =LOWER($J24)&"|"&LOWER($B24) -> 0198ef6d-8543-f668-cedc-b78f8e3bc412|45+ | M24: =LOWER($J24)&"|"&LOWER($C24) -> 0198ef6d-8543-f668-cedc-b78f8e3bc412|age in years, [45, 125[
A25: 0198ef6d-8543-98db-539f-d07c72d29ddb | B25: =IF($G25=$H25-1,$G25&"",$G25&IF($H25=125,"+","-"&$H25-1)) -> 0 | C25: ="Age in years, ["&$G25&", "&$H25&"[" -> Age in years, [0, 1[ | E25: 1 | F25: ="{""lb"":"&$G25&",""lb_in"":true,""ub"":"&$H25&",""ub_in"":false,""unit"":""YEAR""}" -> {"lb":0,"lb_in":true,"ub":1,"ub_in":false,"unit":"YEAR"} | G25: 0 | H25: 1 | I25: =INDEX(ConceptSet!$B:$B,MATCH($J25,ConceptSet!$A:$A,0)) -> AGE_CATEGORY_4 | J25: 0198ef6d-8543-2673-a691-fe8584d0695e | K25: =LOWER($J25)&"|"&LOWER($A25) -> 0198ef6d-8543-2673-a691-fe8584d0695e|0198ef6d-8543-98db-539f-d07c72d29ddb | L25: =LOWER($J25)&"|"&LOWER($B25) -> 0198ef6d-8543-2673-a691-fe8584d0695e|0 | M25: =LOWER($J25)&"|"&LOWER($C25) -> 0198ef6d-8543-2673-a691-fe8584d0695e|age in years, [0, 1[
... A28: 0198ef6d-8543-70a1-1296-358b9a16f485 | B28: =IF($G28=$H28-1,$G28&"",$G28&IF($H28=125,"+","-"&$H28-1)) -> 55-64 | C28: ="Age in years, ["&$G28&", "&$H28&"[" -> Age in years, [55, 65[ | E28: 4 | F28: ="{""lb"":"&$G28&",""lb_in"":true,""ub"":"&$H28&",""ub_in"":false,""unit"":""YEAR""}" -> {"lb":55,"lb_in":true,"ub":65,"ub_in":false,"unit":"YEAR"} | G28: 55 | H28: 65 | I28: =INDEX(ConceptSet!$B:$B,MATCH($J28,ConceptSet!$A:$A,0)) -> AGE_CATEGORY_4 | J28: 0198ef6d-8543-2673-a691-fe8584d0695e | K28: =LOWER($J28)&"|"&LOWER($A28) -> 0198ef6d-8543-2673-a691-fe8584d0695e|0198ef6d-8543-70a1-1296-358b9a16f485 | L28: =LOWER($J28)&"|"&LOWER($B28) -> 0198ef6d-8543-2673-a691-fe8584d0695e|55-64 | M28: =LOWER($J28)&"|"&LOWER($C28) -> 0198ef6d-8543-2673-a691-fe8584d0695e|age in years, [55, 65[
A29: 0198ef6d-8543-595a-1fed-0c02d313b824 | B29: =IF($G29=$H29-1,$G29&"",$G29&IF($H29=48,"+","-"&$H29-1))&"M" -> 0M | C29: ="Age in months, ["&$G29&", "&$H29&"[" -> Age in months, [0, 1[ | E29: 1 | F29: ="{""lb"":"&$G29&",""lb_in"":true,""ub"":"&$H29&",""ub_in"":false,""unit"":""MONTH""}" -> {"lb":0,"lb_in":true,"ub":1,"ub_in":false,"unit":"MONTH"} | G29: 0 | H29: 1 | I29: =INDEX(ConceptSet!$B:$B,MATCH($J29,ConceptSet!$A:$A,0)) -> AGE_CATEGORY_5 | J29: 0198ef6d-8543-cb6b-0c98-c2a7e640e10d | K29: =LOWER($J29)&"|"&LOWER($A29) -> 0198ef6d-8543-cb6b-0c98-c2a7e640e10d|0198ef6d-8543-595a-1fed-0c02d313b824 | L29: =LOWER($J29)&"|"&LOWER($B29) -> 0198ef6d-8543-cb6b-0c98-c2a7e640e10d|0m | M29: =LOWER($J29)&"|"&LOWER($C29) -> 0198ef6d-8543-cb6b-0c98-c2a7e640e10d|age in months, [0, 1[
A30: 0198ef6d-8543-9248-0edb-2477c9364381 | B30: =IF($G30=$H30-1,$G30&"",$G30&IF($H30=48,"+","-"&$H30-1))&"M" -> 1M | C30: ="Age in months, ["&$G30&", "&$H30&"[" -> Age in months, [1, 2[ | E30: 2 | F30: ="{""lb"":"&$G30&",""lb_in"":true,""ub"":"&$H30&",""ub_in"":false,""unit"":""MONTH""}" -> {"lb":1,"lb_in":true,"ub":2,"ub_in":false,"unit":"MONTH"} | G30: 1 | H30: 2 | I30: =INDEX(ConceptSet!$B:$B,MATCH($J30,ConceptSet!$A:$A,0)) -> AGE_CATEGORY_5 | J30: 0198ef6d-8543-cb6b-0c98-c2a7e640e10d | K30: =LOWER($J30)&"|"&LOWER($A30) -> 0198ef6d-8543-cb6b-0c98-c2a7e640e10d|0198ef6d-8543-9248-0edb-2477c9364381 | L30: =LOWER($J30)&"|"&LOWER($B30) -> 0198ef6d-8543-cb6b-0c98-c2a7e640e10d|1m | M30: =LOWER($J30)&"|"&LOWER($C30) -> 0198ef6d-8543-cb6b-0c98-c2a7e640e10d|age in months, [1, 2[
A31: 0198ef6d-8543-fa54-4ee1-8145b37ae29c | B31: =IF($G31=$H31-1,$G31&"",$G31&IF($H31=48,"+","-"&$H31-1))&"M" -> 2M | C31: ="Age in months, ["&$G31&", "&$H31&"[" -> Age in months, [2, 3[ | E31: 3 | F31: ="{""lb"":"&$G31&",""lb_in"":true,""ub"":"&$H31&",""ub_in"":false,""unit"":""MONTH""}" -> {"lb":2,"lb_in":true,"ub":3,"ub_in":false,"unit":"MONTH"} | G31: 2 | H31: 3 | I31: =INDEX(ConceptSet!$B:$B,MATCH($J31,ConceptSet!$A:$A,0)) -> AGE_CATEGORY_5 | J31: 0198ef6d-8543-cb6b-0c98-c2a7e640e10d | K31: =LOWER($J31)&"|"&LOWER($A31) -> 0198ef6d-8543-cb6b-0c98-c2a7e640e10d|0198ef6d-8543-fa54-4ee1-8145b37ae29c | L31: =LOWER($J31)&"|"&LOWER($B31) -> 0198ef6d-8543-cb6b-0c98-c2a7e640e10d|2m | M31: =LOWER($J31)&"|"&LOWER($C31) -> 0198ef6d-8543-cb6b-0c98-c2a7e640e10d|age in months, [2, 3[
A32: 0198ef6d-8543-9154-e58f-dd117f762168 | B32: =IF($G32=$H32-1,$G32&"",$G32&IF($H32=48,"+","-"&$H32-1))&"M" -> 3+M | C32: ="Age in months, ["&$G32&", "&$H32&"[" -> Age in months, [3, 48[ | E32: 4 | F32: ="{""lb"":"&$G32&",""lb_in"":true,""ub"":"&$H32&",""ub_in"":false,""unit"":""MONTH""}" -> {"lb":3,"lb_in":true,"ub":48,"ub_in":false,"unit":"MONTH"} | G32: 3 | H32: 48 | I32: =INDEX(ConceptSet!$B:$B,MATCH($J32,ConceptSet!$A:$A,0)) -> AGE_CATEGORY_5 | J32: 0198ef6d-8543-cb6b-0c98-c2a7e640e10d | K32: =LOWER($J32)&"|"&LOWER($A32) -> 0198ef6d-8543-cb6b-0c98-c2a7e640e10d|0198ef6d-8543-9154-e58f-dd117f762168 | L32: =LOWER($J32)&"|"&LOWER($B32) -> 0198ef6d-8543-cb6b-0c98-c2a7e640e10d|3+m | M32: =LOWER($J32)&"|"&LOWER($C32) -> 0198ef6d-8543-cb6b-0c98-c2a7e640e10d|age in months, [3, 48[

Sheet ConceptRelation
A1: id | B1: from_concept_id | C1: to_concept_id | D1: dm.qc.no_identical_from_to | E1: dm.from_concept.name | F1: dm.to_concept.name | G1: dm.from_concept.concept_set.code | H1: dm.to_concept.concept_set.code | I1: relation
A2: 019965ee-523d-8f13-b94b-16fb4469bb06 | B2: 0198ef6d-8543-1558-187c-47880d4b485e | C2: 0198ef6d-8543-6ac9-4915-b0f74393baa3 | D2: =$B2<>$C2 -> TRUE | E2: =INDEX(Concept!$C:$C,MATCH($B2,Concept!$A:$A,0)) -> Category1_1 | F2: =INDEX(Concept!$C:$C,MATCH($C2,Concept!$A:$A,0)) -> Category2_1 | G2: =INDEX(Concept!$I:$I,MATCH($B2,Concept!$A:$A,0)) -> NOMINAL_1 | H2: =INDEX(Concept!$I:$I,MATCH($C2,Concept!$A:$A,0)) -> NOMINAL_2 | I2: CONTAINS
A3: 019965ee-523d-6fda-d1cb-4f3cb8eb8637 | B3: 0198ef6d-8543-1558-187c-47880d4b485e | C3: 0198ef6d-8543-d8eb-6c3e-2b68e40942f8 | D3: =$B3<>$C3 -> TRUE | E3: =INDEX(Concept!$C:$C,MATCH($B3,Concept!$A:$A,0)) -> Category1_1 | F3: =INDEX(Concept!$C:$C,MATCH($C3,Concept!$A:$A,0)) -> Category2_2 | G3: =INDEX(Concept!$I:$I,MATCH($B3,Concept!$A:$A,0)) -> NOMINAL_1 | H3: =INDEX(Concept!$I:$I,MATCH($C3,Concept!$A:$A,0)) -> NOMINAL_2 | I3: CONTAINS

Sheet RegionSet
A1: id | B1: code | C1: name | D1: region_code_as_label
A2: 0198ef6d-8543-92bb-3d7b-9a6b17e52c7d | B2: PC_L4 | C2: Postal codes - Level 4 | D2: TRUE
A3: 0198ef6d-8543-0ad2-6a86-701cc690b0a4 | B3: PC_L3 | C3: Postal codes - Level 3 | D3: TRUE
A4: 0198ef6d-8543-5e3f-5ed0-dd932e32c2aa | B4: MUN | C4: Municipalities | D4: FALSE
A5: 0198ef6d-8543-ca21-8fc9-aac9c10fe055 | B5: PV | C5: Provinces | D5: FALSE

Sheet Region
A1: id | B1: region_set_id | C1: region_set_name | D1: code | E1: name | F1: centroid_lat | G1: centroid_lon | H1: center_lat | I1: center_lon | J1: dm.key.code | K1: dm.key.name
A2: 0198ef6d-8543-98d5-9df4-4ac64d603502 | B2: 0198ef6d-8543-92bb-3d7b-9a6b17e52c7d | C2: =INDEX(RegionSet!$C:$C,MATCH($B2,RegionSet!$A:$A,0)) -> Postal codes - Level 4 | D2: 1011 | E2: ="PC_"&$D2 -> PC_1011 | F2: 1 | G2: 1 | H2: 1 | I2: 1 | J2: =LOWER($B2&"|"&$D2) -> 0198ef6d-8543-92bb-3d7b-9a6b17e52c7d|1011 | K2: =LOWER($B2&"|"&$E2) -> 0198ef6d-8543-92bb-3d7b-9a6b17e52c7d|pc_1011
A3: 0198ef6d-8543-ae94-efef-2be1b23245af | B3: 0198ef6d-8543-92bb-3d7b-9a6b17e52c7d | C3: =INDEX(RegionSet!$C:$C,MATCH($B3,RegionSet!$A:$A,0)) -> Postal codes - Level 4 | D3: 1012 | E3: ="PC_"&$D3 -> PC_1012 | F3: 1 | G3: 1 | H3: 1 | I3: 1 | J3: =LOWER($B3&"|"&$D3) -> 0198ef6d-8543-92bb-3d7b-9a6b17e52c7d|1012 | K3: =LOWER($B3&"|"&$E3) -> 0198ef6d-8543-92bb-3d7b-9a6b17e52c7d|pc_1012
A4: 0198ef6d-8543-8b5f-18fa-1ed57d0932cc | B4: 0198ef6d-8543-92bb-3d7b-9a6b17e52c7d | C4: =INDEX(RegionSet!$C:$C,MATCH($B4,RegionSet!$A:$A,0)) -> Postal codes - Level 4 | D4: 1013 | E4: ="PC_"&$D4 -> PC_1013 | F4: 1 | G4: 1 | H4: 1 | I4: 1 | J4: =LOWER($B4&"|"&$D4) -> 0198ef6d-8543-92bb-3d7b-9a6b17e52c7d|1013 | K4: =LOWER($B4&"|"&$E4) -> 0198ef6d-8543-92bb-3d7b-9a6b17e52c7d|pc_1013
A5: 0198ef6d-8543-a364-ca72-6ec6f635451c | B5: 0198ef6d-8543-92bb-3d7b-9a6b17e52c7d | C5: =INDEX(RegionSet!$C:$C,MATCH($B5,RegionSet!$A:$A,0)) -> Postal codes - Level 4 | D5: 1021 | E5: ="PC_"&$D5 -> PC_1021 | F5: 1 | G5: 1 | H5: 1 | I5: 1 | J5: =LOWER($B5&"|"&$D5) -> 0198ef6d-8543-92bb-3d7b-9a6b17e52c7d|1021 | K5: =LOWER($B5&"|"&$E5) -> 0198ef6d-8543-92bb-3d7b-9a6b17e52c7d|pc_1021
A6: 0198ef6d-8543-36e6-2666-1cd464720c40 | B6: 0198ef6d-8543-92bb-3d7b-9a6b17e52c7d | C6: =INDEX(RegionSet!$C:$C,MATCH($B6,RegionSet!$A:$A,0)) -> Postal codes - Level 4 | D6: 1022 | E6: ="PC_"&$D6 -> PC_1022 | F6: 1 | G6: 1 | H6: 1 | I6: 1 | J6: =LOWER($B6&"|"&$D6) -> 0198ef6d-8543-92bb-3d7b-9a6b17e52c7d|1022 | K6: =LOWER($B6&"|"&$E6) -> 0198ef6d-8543-92bb-3d7b-9a6b17e52c7d|pc_1022
A7: 0198ef6d-8543-6c09-555d-db3403ec2556 | B7: 0198ef6d-8543-92bb-3d7b-9a6b17e52c7d | C7: =INDEX(RegionSet!$C:$C,MATCH($B7,RegionSet!$A:$A,0)) -> Postal codes - Level 4 | D7: 1023 | E7: ="PC_"&$D7 -> PC_1023 | F7: 1 | G7: 1 | H7: 1 | I7: 1 | J7: =LOWER($B7&"|"&$D7) -> 0198ef6d-8543-92bb-3d7b-9a6b17e52c7d|1023 | K7: =LOWER($B7&"|"&$E7) -> 0198ef6d-8543-92bb-3d7b-9a6b17e52c7d|pc_1023
A8: 0198ef6d-8543-dcdc-9496-52bc01e1c56d | B8: 0198ef6d-8543-0ad2-6a86-701cc690b0a4 | C8: =INDEX(RegionSet!$C:$C,MATCH($B8,RegionSet!$A:$A,0)) -> Postal codes - Level 3 | D8: 101 | E8: ="PC_"&$D8 -> PC_101 | F8: 1 | G8: 1 | H8: 1 | I8: 1 | J8: =LOWER($B8&"|"&$D8) -> 0198ef6d-8543-0ad2-6a86-701cc690b0a4|101 | K8: =LOWER($B8&"|"&$E8) -> 0198ef6d-8543-0ad2-6a86-701cc690b0a4|pc_101
A9: 0198ef6d-8543-633c-9a80-b3ee43366dab | B9: 0198ef6d-8543-0ad2-6a86-701cc690b0a4 | C9: =INDEX(RegionSet!$C:$C,MATCH($B9,RegionSet!$A:$A,0)) -> Postal codes - Level 3 | D9: 102 | E9: ="PC_"&$D9 -> PC_102 | F9: 1 | G9: 1 | H9: 1 | I9: 1 | J9: =LOWER($B9&"|"&$D9) -> 0198ef6d-8543-0ad2-6a86-701cc690b0a4|102 | K9: =LOWER($B9&"|"&$E9) -> 0198ef6d-8543-0ad2-6a86-701cc690b0a4|pc_102
A10: 0198ef6d-8543-83bf-6a77-33c7baa8eca4 | B10: 0198ef6d-8543-5e3f-5ed0-dd932e32c2aa | C10: =INDEX(RegionSet!$C:$C,MATCH($B10,RegionSet!$A:$A,0)) -> Municipalities | D10: A | E10: MUN_A | F10: 1 | G10: 1 | H10: 1 | I10: 1 | J10: =LOWER($B10&"|"&$D10) -> 0198ef6d-8543-5e3f-5ed0-dd932e32c2aa|a | K10: =LOWER($B10&"|"&$E10) -> 0198ef6d-8543-5e3f-5ed0-dd932e32c2aa|mun_a
A11: 0198ef6d-8543-5e67-2557-0e2746373e1d | B11: 0198ef6d-8543-5e3f-5ed0-dd932e32c2aa | C11: =INDEX(RegionSet!$C:$C,MATCH($B11,RegionSet!$A:$A,0)) -> Municipalities | D11: B | E11: MUN_B | F11: 1 | G11: 1 | H11: 1 | I11: 1 | J11: =LOWER($B11&"|"&$D11) -> 0198ef6d-8543-5e3f-5ed0-dd932e32c2aa|b | K11: =LOWER($B11&"|"&$E11) -> 0198ef6d-8543-5e3f-5ed0-dd932e32c2aa|mun_b
A12: 0198ef6d-8543-b5ae-6be3-ce46ae7b36cb | B12: 0198ef6d-8543-5e3f-5ed0-dd932e32c2aa | C12: =INDEX(RegionSet!$C:$C,MATCH($B12,RegionSet!$A:$A,0)) -> Municipalities | D12: C | E12: MUN_C | F12: 1 | G12: 1 | H12: 1 | I12: 1 | J12: =LOWER($B12&"|"&$D12) -> 0198ef6d-8543-5e3f-5ed0-dd932e32c2aa|c | K12: =LOWER($B12&"|"&$E12) -> 0198ef6d-8543-5e3f-5ed0-dd932e32c2aa|mun_c
A13: 0198ef6d-8543-2881-ac87-bb85405cfd45 | B13: 0198ef6d-8543-ca21-8fc9-aac9c10fe055 | C13: =INDEX(RegionSet!$C:$C,MATCH($B13,RegionSet!$A:$A,0)) -> Provinces | D13: PV_1 | E13: Province_1 | F13: 1 | G13: 1 | H13: 1 | I13: 1 | J13: =LOWER($B13&"|"&$D13) -> 0198ef6d-8543-ca21-8fc9-aac9c10fe055|pv_1 | K13: =LOWER($B13&"|"&$E13) -> 0198ef6d-8543-ca21-8fc9-aac9c10fe055|province_1
A14: 0198ef6d-8543-492f-605f-9f24aff04b0c | B14: 0198ef6d-8543-ca21-8fc9-aac9c10fe055 | C14: =INDEX(RegionSet!$C:$C,MATCH($B14,RegionSet!$A:$A,0)) -> Provinces | D14: PV_2 | E14: Province_2 | F14: 1 | G14: 1 | H14: 1 | I14: 1 | J14: =LOWER($B14&"|"&$D14) -> 0198ef6d-8543-ca21-8fc9-aac9c10fe055|pv_2 | K14: =LOWER($B14&"|"&$E14) -> 0198ef6d-8543-ca21-8fc9-aac9c10fe055|province_2
A15: 0198ef6d-8543-e169-e90c-b16046775a79 | B15: 0198ef6d-8543-ca21-8fc9-aac9c10fe055 | C15: =INDEX(RegionSet!$C:$C,MATCH($B15,RegionSet!$A:$A,0)) -> Provinces | D15: PV_3 | E15: Province_3 | F15: 1 | G15: 1 | H15: 1 | I15: 1 | J15: =LOWER($B15&"|"&$D15) -> 0198ef6d-8543-ca21-8fc9-aac9c10fe055|pv_3 | K15: =LOWER($B15&"|"&$E15) -> 0198ef6d-8543-ca21-8fc9-aac9c10fe055|province_3

Sheet RegionRelation
A1: id | B1: from_region_id | C1: from_region_name | D1: to_region_id | E1: to_region_name | F1: relation
A2: 0198ef6d-8543-0c0b-4a83-bc5645c27a12 | B2: 0198ef6d-8543-dcdc-9496-52bc01e1c56d | C2: =INDEX(Region!$E:$E,MATCH($B2,Region!$A:$A,0)) -> PC_101 | D2: 0198ef6d-8543-98d5-9df4-4ac64d603502 | E2: =INDEX(Region!$E:$E,MATCH($D2,Region!$A:$A,0)) -> PC_1011 | F2: CONTAINS
A3: 0198ef6d-8543-6900-d021-0a967bc5a835 | B3: 0198ef6d-8543-dcdc-9496-52bc01e1c56d | C3: =INDEX(Region!$E:$E,MATCH($B3,Region!$A:$A,0)) -> PC_101 | D3: 0198ef6d-8543-ae94-efef-2be1b23245af | E3: =INDEX(Region!$E:$E,MATCH($D3,Region!$A:$A,0)) -> PC_1012 | F3: CONTAINS
A4: 0198ef6d-8543-b77a-986a-970332b990bf | B4: 0198ef6d-8543-dcdc-9496-52bc01e1c56d | C4: =INDEX(Region!$E:$E,MATCH($B4,Region!$A:$A,0)) -> PC_101 | D4: 0198ef6d-8543-8b5f-18fa-1ed57d0932cc | E4: =INDEX(Region!$E:$E,MATCH($D4,Region!$A:$A,0)) -> PC_1013 | F4: CONTAINS
A5: 0198ef6d-8543-4356-94fa-71fde8f78147 | B5: 0198ef6d-8543-633c-9a80-b3ee43366dab | C5: =INDEX(Region!$E:$E,MATCH($B5,Region!$A:$A,0)) -> PC_102 | D5: 0198ef6d-8543-a364-ca72-6ec6f635451c | E5: =INDEX(Region!$E:$E,MATCH($D5,Region!$A:$A,0)) -> PC_1021 | F5: CONTAINS
A6: 0198ef6d-8543-446a-e48d-84d9816d7653 | B6: 0198ef6d-8543-633c-9a80-b3ee43366dab | C6: =INDEX(Region!$E:$E,MATCH($B6,Region!$A:$A,0)) -> PC_102 | D6: 0198ef6d-8543-36e6-2666-1cd464720c40 | E6: =INDEX(Region!$E:$E,MATCH($D6,Region!$A:$A,0)) -> PC_1022 | F6: CONTAINS
A7: 0198ef6d-8543-bf0a-5017-971b46110913 | B7: 0198ef6d-8543-633c-9a80-b3ee43366dab | C7: =INDEX(Region!$E:$E,MATCH($B7,Region!$A:$A,0)) -> PC_102 | D7: 0198ef6d-8543-6c09-555d-db3403ec2556 | E7: =INDEX(Region!$E:$E,MATCH($D7,Region!$A:$A,0)) -> PC_1023 | F7: CONTAINS
A8: 0198ef6d-8543-9029-dc48-eaa05a343a26 | B8: 0198ef6d-8543-83bf-6a77-33c7baa8eca4 | C8: =INDEX(Region!$E:$E,MATCH($B8,Region!$A:$A,0)) -> MUN_A | D8: 0198ef6d-8543-98d5-9df4-4ac64d603502 | E8: =INDEX(Region!$E:$E,MATCH($D8,Region!$A:$A,0)) -> PC_1011 | F8: CONTAINS
A9: 0198ef6d-8543-6a58-c520-ee5673f2e787 | B9: 0198ef6d-8543-83bf-6a77-33c7baa8eca4 | C9: =INDEX(Region!$E:$E,MATCH($B9,Region!$A:$A,0)) -> MUN_A | D9: 0198ef6d-8543-ae94-efef-2be1b23245af | E9: =INDEX(Region!$E:$E,MATCH($D9,Region!$A:$A,0)) -> PC_1012 | F9: CONTAINS
A10: 0198ef6d-8543-5d0c-da5a-9488f8a33242 | B10: 0198ef6d-8543-5e67-2557-0e2746373e1d | C10: =INDEX(Region!$E:$E,MATCH($B10,Region!$A:$A,0)) -> MUN_B | D10: 0198ef6d-8543-8b5f-18fa-1ed57d0932cc | E10: =INDEX(Region!$E:$E,MATCH($D10,Region!$A:$A,0)) -> PC_1013 | F10: CONTAINS
A11: 0198ef6d-8543-4f94-dbed-811f8c7fea6e | B11: 0198ef6d-8543-5e67-2557-0e2746373e1d | C11: =INDEX(Region!$E:$E,MATCH($B11,Region!$A:$A,0)) -> MUN_B | D11: 0198ef6d-8543-a364-ca72-6ec6f635451c | E11: =INDEX(Region!$E:$E,MATCH($D11,Region!$A:$A,0)) -> PC_1021 | F11: CONTAINS
A12: 0198ef6d-8543-0012-5a19-386a453bb806 | B12: 0198ef6d-8543-b5ae-6be3-ce46ae7b36cb | C12: =INDEX(Region!$E:$E,MATCH($B12,Region!$A:$A,0)) -> MUN_C | D12: 0198ef6d-8543-36e6-2666-1cd464720c40 | E12: =INDEX(Region!$E:$E,MATCH($D12,Region!$A:$A,0)) -> PC_1022 | F12: CONTAINS
A13: 0198ef6d-8543-9155-eca8-a17eb16e9c36 | B13: 0198ef6d-8543-b5ae-6be3-ce46ae7b36cb | C13: =INDEX(Region!$E:$E,MATCH($B13,Region!$A:$A,0)) -> MUN_C | D13: 0198ef6d-8543-6c09-555d-db3403ec2556 | E13: =INDEX(Region!$E:$E,MATCH($D13,Region!$A:$A,0)) -> PC_1023 | F13: CONTAINS
... A22: 0198ef6d-8543-7e4c-8422-4014740e6a01 | B22: 0198ef6d-8543-492f-605f-9f24aff04b0c | C22: =INDEX(Region!$E:$E,MATCH($B22,Region!$A:$A,0)) -> Province_2 | D22: 0198ef6d-8543-b5ae-6be3-ce46ae7b36cb | E22: =INDEX(Region!$E:$E,MATCH($D22,Region!$A:$A,0)) -> MUN_C | F22: CONTAINS

Sheet Organization
A1: id | B1: name | C1: legal_entity_code | D1: legal_region_id | E1: legal_region
A2: 018d074d-ea0c-e942-07db-a3cc0ba1d653 | B2: org1 | C2: org1
A3: 0195d18c-1c92-0ed4-2e94-b4f66d82baf3 | B3: org2 | C3: org2
A4: 0195d18c-1c92-52b3-93e0-43dc1f2aa037 | B4: org3 | C4: org3
A5: 0195d18c-1c92-d419-4c71-a570f428499b | B5: org4 | C5: org4
A6: 0195d18c-1c93-02a2-6920-7e4dbfb73ce0 | B6: org5 | C6: org5

Sheet DataCollection
A1: id | B1: name | C1: description
A2: 0195d18c-1ca2-a23d-1f64-00271f63199c | B2: data_collection1 | C2: ="dc"&RIGHT($B2,LEN($B2)-15) -> dc1
A3: 0195d18c-1ca2-2a29-96a5-37c6bf87f586 | B3: data_collection2 | C3: ="dc"&RIGHT($B3,LEN($B3)-15) -> dc2
A4: 0195d18c-1ca2-3a4f-1878-fbe3282c9c76 | B4: data_collection3 | C4: ="dc"&RIGHT($B4,LEN($B4)-15) -> dc3
A5: 0195d18c-1ca2-e55a-608d-a42fc6f948e1 | B5: data_collection4 | C5: ="dc"&RIGHT($B5,LEN($B5)-15) -> dc4
A6: 0195d18c-1ca2-b728-a2a1-d2a4cf7b8eb8 | B6: data_collection5 | C6: ="dc"&RIGHT($B6,LEN($B6)-15) -> dc5
A7: 0195d18c-1ca3-f309-f6f1-e4807afe3802 | B7: data_collection6 | C7: ="dc"&RIGHT($B7,LEN($B7)-15) -> dc6
A8: 0195d18c-1ca3-db40-a2a8-6dc905d6c1e9 | B8: data_collection7 | C8: ="dc"&RIGHT($B8,LEN($B8)-15) -> dc7
A9: 0195d18c-1ca3-da0a-44bb-877b3a1eb73e | B9: data_collection8 | C9: ="dc"&RIGHT($B9,LEN($B9)-15) -> dc8
A10: 0195d18c-1ca3-4d34-d0e9-8f024ad8651a | B10: data_collection9 | C10: ="dc"&RIGHT($B10,LEN($B10)-15) -> dc9
A11: 0195d18c-1ca3-11a2-bf20-8eaaa09cc070 | B11: data_collection10 | C11: ="dc"&RIGHT($B11,LEN($B11)-15) -> dc10
A12: 0195d18c-1ca4-e691-7ebd-8ecb1a16a2ed | B12: data_collection11 | C12: ="dc"&RIGHT($B12,LEN($B12)-15) -> dc11

Sheet User
A1: id | B1: key | C1: email | D1: name | E1: is_active | F1: roles | G1: organization_id | H1: dm.organization_name | I1: dm.roles_is_root | J1: dm.roles_is_app_admin | K1: dm.roles_is_refdata_admin | L1: dm.roles_is_org_user | M1: dm.is_ge_app_admin
A2: 019542cc-8225-8f5d-fa30-d9c3f2629703 | B2: root1_1@org1_org | C2: root1_1@org1_org | D2: =LEFT(C2,FIND("@",C2)-1) -> root1_1 | E2: TRUE | F2: ["CASEDB_ROOT"] | G2: 018d074d-ea0c-e942-07db-a3cc0ba1d653 | H2: =INDEX(Organization!$B:$B,MATCH($G2,Organization!$A:$A,0)) -> org1 | I2: =ISNUMBER(SEARCH("ROOT", F2)) -> TRUE | J2: =ISNUMBER(SEARCH("APP_ADMIN", $F2)) -> FALSE | K2: =ISNUMBER(SEARCH("METADATA_ADMIN", $F2)) -> FALSE | L2: =ISNUMBER(SEARCH("ORG_USER", $F2)) -> FALSE | M2: =OR($I2,$J2) -> TRUE
A3: 0195d18c-1c92-110e-81c1-75ba0fec4494 | B3: app_admin1_1@org1_org | C3: app_admin1_1@org1_org | D3: =LEFT(C3,FIND("@",C3)-1) -> app_admin1_1 | E3: TRUE | F3: ["CASEDB_APP_ADMIN"] | G3: 018d074d-ea0c-e942-07db-a3cc0ba1d653 | H3: =INDEX(Organization!$B:$B,MATCH($G3,Organization!$A:$A,0)) -> org1 | I3: =ISNUMBER(SEARCH("ROOT", F3)) -> FALSE | J3: =ISNUMBER(SEARCH("APP_ADMIN", $F3)) -> TRUE | K3: =ISNUMBER(SEARCH("METADATA_ADMIN", $F3)) -> FALSE | L3: =ISNUMBER(SEARCH("ORG_USER", $F3)) -> FALSE | M3: =OR($I3,$J3) -> TRUE
A4: 0195d18c-1c93-bcbb-eea8-94332d77b172 | B4: refdata_admin1_1@org1_org | C4: refdata_admin1_1@org1_org | D4: =LEFT(C4,FIND("@",C4)-1) -> refdata_admin1_1 | E4: TRUE | F4: ["CASEDB_REFDATA_ADMIN"] | G4: 018d074d-ea0c-e942-07db-a3cc0ba1d653 | H4: =INDEX(Organization!$B:$B,MATCH($G4,Organization!$A:$A,0)) -> org1 | I4: =ISNUMBER(SEARCH("ROOT", F4)) -> FALSE | J4: =ISNUMBER(SEARCH("APP_ADMIN", $F4)) -> FALSE | K4: =ISNUMBER(SEARCH("METADATA_ADMIN", $F4)) -> FALSE | L4: =ISNUMBER(SEARCH("ORG_USER", $F4)) -> FALSE | M4: =OR($I4,$J4) -> FALSE
A5: 0195d18c-1c93-1f4b-8c40-19223d6c7a8c | B5: org_admin1_1@org1_org | C5: org_admin1_1@org1_org | D5: =LEFT(C5,FIND("@",C5)-1) -> org_admin1_1 | E5: TRUE | F5: ["CASEDB_ORG_ADMIN"] | G5: 018d074d-ea0c-e942-07db-a3cc0ba1d653 | H5: =INDEX(Organization!$B:$B,MATCH($G5,Organization!$A:$A,0)) -> org1 | I5: =ISNUMBER(SEARCH("ROOT", F5)) -> FALSE | J5: =ISNUMBER(SEARCH("APP_ADMIN", $F5)) -> FALSE | K5: =ISNUMBER(SEARCH("METADATA_ADMIN", $F5)) -> FALSE | L5: =ISNUMBER(SEARCH("ORG_USER", $F5)) -> FALSE | M5: =OR($I5,$J5) -> FALSE
A6: 0195d18c-1c95-2343-576e-0c14e0a4505d | B6: org_admin2_1@org2_org | C6: org_admin2_1@org2_org | D6: =LEFT(C6,FIND("@",C6)-1) -> org_admin2_1 | E6: TRUE | F6: ["CASEDB_ORG_ADMIN"] | G6: 0195d18c-1c92-0ed4-2e94-b4f66d82baf3 | H6: =INDEX(Organization!$B:$B,MATCH($G6,Organization!$A:$A,0)) -> org2 | I6: =ISNUMBER(SEARCH("ROOT", F6)) -> FALSE | J6: =ISNUMBER(SEARCH("APP_ADMIN", $F6)) -> FALSE | K6: =ISNUMBER(SEARCH("METADATA_ADMIN", $F6)) -> FALSE | L6: =ISNUMBER(SEARCH("ORG_USER", $F6)) -> FALSE | M6: =OR($I6,$J6) -> FALSE
A7: 0195d18c-1c96-59a8-d2a6-70a3b13175a1 | B7: org_admin3_1@org3_org | C7: org_admin3_1@org3_org | D7: =LEFT(C7,FIND("@",C7)-1) -> org_admin3_1 | E7: TRUE | F7: ["CASEDB_ORG_ADMIN"] | G7: 0195d18c-1c92-52b3-93e0-43dc1f2aa037 | H7: =INDEX(Organization!$B:$B,MATCH($G7,Organization!$A:$A,0)) -> org3 | I7: =ISNUMBER(SEARCH("ROOT", F7)) -> FALSE | J7: =ISNUMBER(SEARCH("APP_ADMIN", $F7)) -> FALSE | K7: =ISNUMBER(SEARCH("METADATA_ADMIN", $F7)) -> FALSE | L7: =ISNUMBER(SEARCH("ORG_USER", $F7)) -> FALSE | M7: =OR($I7,$J7) -> FALSE
A8: 0195d18c-1c96-08ed-1241-eaf327bd1ffc | B8: org_admin4_1@org4_org | C8: org_admin4_1@org4_org | D8: =LEFT(C8,FIND("@",C8)-1) -> org_admin4_1 | E8: TRUE | F8: ["CASEDB_ORG_ADMIN"] | G8: 0195d18c-1c92-d419-4c71-a570f428499b | H8: =INDEX(Organization!$B:$B,MATCH($G8,Organization!$A:$A,0)) -> org4 | I8: =ISNUMBER(SEARCH("ROOT", F8)) -> FALSE | J8: =ISNUMBER(SEARCH("APP_ADMIN", $F8)) -> FALSE | K8: =ISNUMBER(SEARCH("METADATA_ADMIN", $F8)) -> FALSE | L8: =ISNUMBER(SEARCH("ORG_USER", $F8)) -> FALSE | M8: =OR($I8,$J8) -> FALSE
A9: 0195d18c-1c97-faac-82eb-3e357979b402 | B9: org_admin5_1@org5_org | C9: org_admin5_1@org5_org | D9: =LEFT(C9,FIND("@",C9)-1) -> org_admin5_1 | E9: TRUE | F9: ["CASEDB_ORG_ADMIN"] | G9: 0195d18c-1c93-02a2-6920-7e4dbfb73ce0 | H9: =INDEX(Organization!$B:$B,MATCH($G9,Organization!$A:$A,0)) -> org5 | I9: =ISNUMBER(SEARCH("ROOT", F9)) -> FALSE | J9: =ISNUMBER(SEARCH("APP_ADMIN", $F9)) -> FALSE | K9: =ISNUMBER(SEARCH("METADATA_ADMIN", $F9)) -> FALSE | L9: =ISNUMBER(SEARCH("ORG_USER", $F9)) -> FALSE | M9: =OR($I9,$J9) -> FALSE
A10: 0195d18c-1c98-7e0b-0c91-8cafbdb2c852 | B10: org_user1_1@org1_org | C10: org_user1_1@org1_org | D10: =LEFT(C10,FIND("@",C10)-1) -> org_user1_1 | E10: TRUE | F10: ["CASEDB_ORG_USER"] | G10: 018d074d-ea0c-e942-07db-a3cc0ba1d653 | H10: =INDEX(Organization!$B:$B,MATCH($G10,Organization!$A:$A,0)) -> org1 | I10: =ISNUMBER(SEARCH("ROOT", F10)) -> FALSE | J10: =ISNUMBER(SEARCH("APP_ADMIN", $F10)) -> FALSE | K10: =ISNUMBER(SEARCH("METADATA_ADMIN", $F10)) -> FALSE | L10: =ISNUMBER(SEARCH("ORG_USER", $F10)) -> TRUE | M10: =OR($I10,$J10) -> FALSE
A11: 0195d18c-1c98-5a1e-55b9-67b877813693 | B11: org_user1_2@org1_org | C11: org_user1_2@org1_org | D11: =LEFT(C11,FIND("@",C11)-1) -> org_user1_2 | E11: TRUE | F11: ["CASEDB_ORG_USER"] | G11: 018d074d-ea0c-e942-07db-a3cc0ba1d653 | H11: =INDEX(Organization!$B:$B,MATCH($G11,Organization!$A:$A,0)) -> org1 | I11: =ISNUMBER(SEARCH("ROOT", F11)) -> FALSE | J11: =ISNUMBER(SEARCH("APP_ADMIN", $F11)) -> FALSE | K11: =ISNUMBER(SEARCH("METADATA_ADMIN", $F11)) -> FALSE | L11: =ISNUMBER(SEARCH("ORG_USER", $F11)) -> TRUE | M11: =OR($I11,$J11) -> FALSE
A12: 0195d18c-1c99-03eb-f1b4-a88daae1b74c | B12: org_user1_3@org1_org | C12: org_user1_3@org1_org | D12: =LEFT(C12,FIND("@",C12)-1) -> org_user1_3 | E12: TRUE | F12: ["CASEDB_ORG_USER"] | G12: 018d074d-ea0c-e942-07db-a3cc0ba1d653 | H12: =INDEX(Organization!$B:$B,MATCH($G12,Organization!$A:$A,0)) -> org1 | I12: =ISNUMBER(SEARCH("ROOT", F12)) -> FALSE | J12: =ISNUMBER(SEARCH("APP_ADMIN", $F12)) -> FALSE | K12: =ISNUMBER(SEARCH("METADATA_ADMIN", $F12)) -> FALSE | L12: =ISNUMBER(SEARCH("ORG_USER", $F12)) -> TRUE | M12: =OR($I12,$J12) -> FALSE
A13: 0195d18c-1c99-a68b-99dd-a489908e8df1 | B13: org_user1_4@org1_org | C13: org_user1_4@org1_org | D13: =LEFT(C13,FIND("@",C13)-1) -> org_user1_4 | E13: TRUE | F13: ["CASEDB_ORG_USER"] | G13: 018d074d-ea0c-e942-07db-a3cc0ba1d653 | H13: =INDEX(Organization!$B:$B,MATCH($G13,Organization!$A:$A,0)) -> org1 | I13: =ISNUMBER(SEARCH("ROOT", F13)) -> FALSE | J13: =ISNUMBER(SEARCH("APP_ADMIN", $F13)) -> FALSE | K13: =ISNUMBER(SEARCH("METADATA_ADMIN", $F13)) -> FALSE | L13: =ISNUMBER(SEARCH("ORG_USER", $F13)) -> TRUE | M13: =OR($I13,$J13) -> FALSE
... A29: 0195d18c-1ca1-d3df-24f3-7aac91cc3f3a | B29: org_user5_4@org5_org | C29: org_user5_4@org5_org | D29: =LEFT(C29,FIND("@",C29)-1) -> org_user5_4 | E29: TRUE | F29: ["CASEDB_ORG_USER"] | G29: 0195d18c-1c93-02a2-6920-7e4dbfb73ce0 | H29: =INDEX(Organization!$B:$B,MATCH($G29,Organization!$A:$A,0)) -> org5 | I29: =ISNUMBER(SEARCH("ROOT", F29)) -> FALSE | J29: =ISNUMBER(SEARCH("APP_ADMIN", $F29)) -> FALSE | K29: =ISNUMBER(SEARCH("METADATA_ADMIN", $F29)) -> FALSE | L29: =ISNUMBER(SEARCH("ORG_USER", $F29)) -> TRUE | M29: =OR($I29,$J29) -> FALSE

Sheet UserInvitation
A1: id | B1: key | C1: email | D1: dm.name | E1: token | F1: expires_at | G1: roles | H1: invited_by_user_id | I1: dm.invited_by_user | J1: organization_id | K1: dm.organization
A2: 0195d18c-1c91-417d-6686-2f6cb5ff95b9 | B2: app_admin1_1@org1_org | C2: app_admin1_1@org1_org | D2: =LEFT($C2,LEN($C2)-9) -> app_admin1_1 | E2: 26dcbff8-2925-4078-90ad-bbe74165f6b3 | F2: 45743.391 | G2: ["CASEDB_APP_ADMIN"] | H2: 019542cc-8225-8f5d-fa30-d9c3f2629703 | I2: =INDEX(User!$D:$D,MATCH($H2,User!$A:$A,0)) -> root1_1 | J2: 018d074d-ea0c-e942-07db-a3cc0ba1d653 | K2: =INDEX(Organization!$B:$B,MATCH($J2,Organization!$A:$A,0)) -> org1
A3: 0195d18c-1c93-6939-20ec-9c4c00d851c1 | B3: refdata_admin1_1@org1_org | C3: refdata_admin1_1@org1_org | D3: =LEFT($C3,LEN($C3)-9) -> refdata_admin1_1 | E3: 10ad47a6-0901-408c-bfc0-a05a4e83af4e | F3: 45743.391 | G3: ["CASEDB_REFDATA_ADMIN"] | H3: 0195d18c-1c92-110e-81c1-75ba0fec4494 | I3: =INDEX(User!$D:$D,MATCH($H3,User!$A:$A,0)) -> app_admin1_1 | J3: 018d074d-ea0c-e942-07db-a3cc0ba1d653 | K3: =INDEX(Organization!$B:$B,MATCH($J3,Organization!$A:$A,0)) -> org1
A4: 0195d18c-1c93-ec90-9271-1015b282d4b3 | B4: org_admin1_1@org1_org | C4: org_admin1_1@org1_org | D4: =LEFT($C4,LEN($C4)-9) -> org_admin1_1 | E4: 6f8d5681-2c6c-44ae-9522-178a45deaf16 | F4: 45743.391 | G4: ["CASEDB_ORG_ADMIN"] | H4: 0195d18c-1c92-110e-81c1-75ba0fec4494 | I4: =INDEX(User!$D:$D,MATCH($H4,User!$A:$A,0)) -> app_admin1_1 | J4: 018d074d-ea0c-e942-07db-a3cc0ba1d653 | K4: =INDEX(Organization!$B:$B,MATCH($J4,Organization!$A:$A,0)) -> org1
A5: 0195d18c-1c95-0879-fcf0-17e1131cc29b | B5: org_admin2_1@org2_org | C5: org_admin2_1@org2_org | D5: =LEFT($C5,LEN($C5)-9) -> org_admin2_1 | E5: 839e81a3-3184-4c47-bf1c-7f1f964fe280 | F5: 45743.391 | G5: ["CASEDB_ORG_ADMIN"] | H5: 0195d18c-1c92-110e-81c1-75ba0fec4494 | I5: =INDEX(User!$D:$D,MATCH($H5,User!$A:$A,0)) -> app_admin1_1 | J5: 0195d18c-1c92-0ed4-2e94-b4f66d82baf3 | K5: =INDEX(Organization!$B:$B,MATCH($J5,Organization!$A:$A,0)) -> org2
A6: 0195d18c-1c95-a854-581f-4e9ae9d85b92 | B6: org_admin3_1@org3_org | C6: org_admin3_1@org3_org | D6: =LEFT($C6,LEN($C6)-9) -> org_admin3_1 | E6: 1ad1489c-d661-475a-958d-c6684f5dd5d2 | F6: 45743.391 | G6: ["CASEDB_ORG_ADMIN"] | H6: 0195d18c-1c92-110e-81c1-75ba0fec4494 | I6: =INDEX(User!$D:$D,MATCH($H6,User!$A:$A,0)) -> app_admin1_1 | J6: 0195d18c-1c92-52b3-93e0-43dc1f2aa037 | K6: =INDEX(Organization!$B:$B,MATCH($J6,Organization!$A:$A,0)) -> org3
A7: 0195d18c-1c96-ec9c-d51d-0eec040d7ffd | B7: org_admin4_1@org4_org | C7: org_admin4_1@org4_org | D7: =LEFT($C7,LEN($C7)-9) -> org_admin4_1 | E7: ac3ef8cf-b738-458a-9250-e68a9452546b | F7: 45743.391 | G7: ["CASEDB_ORG_ADMIN"] | H7: 0195d18c-1c92-110e-81c1-75ba0fec4494 | I7: =INDEX(User!$D:$D,MATCH($H7,User!$A:$A,0)) -> app_admin1_1 | J7: 0195d18c-1c92-d419-4c71-a570f428499b | K7: =INDEX(Organization!$B:$B,MATCH($J7,Organization!$A:$A,0)) -> org4
A8: 0195d18c-1c97-bf94-f109-505bfb986995 | B8: org_admin5_1@org5_org | C8: org_admin5_1@org5_org | D8: =LEFT($C8,LEN($C8)-9) -> org_admin5_1 | E8: 2a653a89-2320-41a9-8163-356114c3ba28 | F8: 45743.391 | G8: ["CASEDB_ORG_ADMIN"] | H8: 0195d18c-1c92-110e-81c1-75ba0fec4494 | I8: =INDEX(User!$D:$D,MATCH($H8,User!$A:$A,0)) -> app_admin1_1 | J8: 0195d18c-1c93-02a2-6920-7e4dbfb73ce0 | K8: =INDEX(Organization!$B:$B,MATCH($J8,Organization!$A:$A,0)) -> org5
A9: 0195d18c-1c98-4085-5812-4a69516f59ae | B9: org_user1_1@org1_org | C9: org_user1_1@org1_org | D9: =LEFT($C9,LEN($C9)-9) -> org_user1_1 | E9: feb33345-6e94-4f64-807e-c8f4a6e9e232 | F9: 45743.391 | G9: ["CASEDB_ORG_USER"] | H9: 0195d18c-1c92-110e-81c1-75ba0fec4494 | I9: =INDEX(User!$D:$D,MATCH($H9,User!$A:$A,0)) -> app_admin1_1 | J9: 018d074d-ea0c-e942-07db-a3cc0ba1d653 | K9: =INDEX(Organization!$B:$B,MATCH($J9,Organization!$A:$A,0)) -> org1
A10: 0195d18c-1c98-91f0-72bb-c9c9bbd287c5 | B10: org_user1_2@org1_org | C10: org_user1_2@org1_org | D10: =LEFT($C10,LEN($C10)-9) -> org_user1_2 | E10: e2049ab9-9249-4847-852a-6b43b8d12ff8 | F10: 45743.391 | G10: ["CASEDB_ORG_USER"] | H10: 0195d18c-1c92-110e-81c1-75ba0fec4494 | I10: =INDEX(User!$D:$D,MATCH($H10,User!$A:$A,0)) -> app_admin1_1 | J10: 018d074d-ea0c-e942-07db-a3cc0ba1d653 | K10: =INDEX(Organization!$B:$B,MATCH($J10,Organization!$A:$A,0)) -> org1
A11: 0195d18c-1c98-90fe-f86a-b3ff952dc368 | B11: org_user1_3@org1_org | C11: org_user1_3@org1_org | D11: =LEFT($C11,LEN($C11)-9) -> org_user1_3 | E11: 973418bc-df76-4c74-bf1f-8919b9295848 | F11: 45743.391 | G11: ["CASEDB_ORG_USER"] | H11: 0195d18c-1c92-110e-81c1-75ba0fec4494 | I11: =INDEX(User!$D:$D,MATCH($H11,User!$A:$A,0)) -> app_admin1_1 | J11: 018d074d-ea0c-e942-07db-a3cc0ba1d653 | K11: =INDEX(Organization!$B:$B,MATCH($J11,Organization!$A:$A,0)) -> org1
A12: 0195d18c-1c99-b943-3900-1de44aa64da4 | B12: org_user1_4@org1_org | C12: org_user1_4@org1_org | D12: =LEFT($C12,LEN($C12)-9) -> org_user1_4 | E12: b9782553-9cf2-4fa6-9ad4-aae54307d988 | F12: 45743.391 | G12: ["CASEDB_ORG_USER"] | H12: 0195d18c-1c92-110e-81c1-75ba0fec4494 | I12: =INDEX(User!$D:$D,MATCH($H12,User!$A:$A,0)) -> app_admin1_1 | J12: 018d074d-ea0c-e942-07db-a3cc0ba1d653 | K12: =INDEX(Organization!$B:$B,MATCH($J12,Organization!$A:$A,0)) -> org1
A13: 0195d18c-1c99-ee95-2cb4-c932da0954b7 | B13: org_user2_1@org2_org | C13: org_user2_1@org2_org | D13: =LEFT($C13,LEN($C13)-9) -> org_user2_1 | E13: a3c4d7fd-06b7-43b7-bdfa-0cb99f4d15db | F13: 45743.391 | G13: ["CASEDB_ORG_USER"] | H13: 0195d18c-1c92-110e-81c1-75ba0fec4494 | I13: =INDEX(User!$D:$D,MATCH($H13,User!$A:$A,0)) -> app_admin1_1 | J13: 0195d18c-1c92-0ed4-2e94-b4f66d82baf3 | K13: =INDEX(Organization!$B:$B,MATCH($J13,Organization!$A:$A,0)) -> org2
... A28: 0195d18c-1ca1-507d-514e-7f6784ab639e | B28: org_user5_4@org5_org | C28: org_user5_4@org5_org | D28: =LEFT($C28,LEN($C28)-9) -> org_user5_4 | E28: 2ee7a962-2bc6-4e19-adad-f0c7597a075b | F28: 45743.391 | G28: ["CASEDB_ORG_USER"] | H28: 0195d18c-1c92-110e-81c1-75ba0fec4494 | I28: =INDEX(User!$D:$D,MATCH($H28,User!$A:$A,0)) -> app_admin1_1 | J28: 0195d18c-1c93-02a2-6920-7e4dbfb73ce0 | K28: =INDEX(Organization!$B:$B,MATCH($J28,Organization!$A:$A,0)) -> org5

Sheet Dim
A1: id | B1: dim_type | C1: code | D1: label | E1: rank | F1: col_code_prefix | G1: description | H1: props
A2: 0198ef6d-8543-8d7e-a786-a78961958b68 | B2: TEXT | C2: nominal1 | D2: nominal1 | E2: 1 | G2: =$C2&"("&$B2&")" -> nominal1(TEXT) | H2: {}
A3: 0198ef6d-8543-4e10-dadc-606a590cbf81 | B3: TEXT | C3: nominal2 | D3: nominal2 | E3: =E2+1 -> 2 | G3: =$C3&"("&$B3&")" -> nominal2(TEXT) | H3: {}
A4: 0198ef6d-8543-4b57-ccc7-1e34bcca2de1 | B4: TEXT | C4: ordinal1 | D4: ordinal1 | E4: =E3+1 -> 3 | G4: =$C4&"("&$B4&")" -> ordinal1(TEXT) | H4: {}
A5: 0198ef6d-8543-9c78-54a7-6b4c2ca6ce88 | B5: TEXT | C5: ordinal2 | D5: ordinal2 | E5: =E4+1 -> 4 | G5: =$C5&"("&$B5&")" -> ordinal2(TEXT) | H5: {}
A6: 0198ef6d-8543-6a7f-4553-b7280cc2ab9b | B6: TEXT | C6: regex1 | D6: regex1 | E6: =E5+1 -> 5 | G6: =$C6&"("&$B6&")" -> regex1(TEXT) | H6: {}
A7: 0198ef6d-8543-5e3c-cec3-8db0ccbd38fa | B7: TEXT | C7: regex2 | D7: regex2 | E7: =E6+1 -> 6 | G7: =$C7&"("&$B7&")" -> regex2(TEXT) | H7: {}
A8: 0198ef6d-8543-0b52-87e5-431792f951a2 | B8: TEXT | C8: text1 | D8: text1 | E8: =E7+1 -> 7 | G8: =$C8&"("&$B8&")" -> text1(TEXT) | H8: {}
A9: 0198ef6d-8543-e0a4-1718-6ae19c4f6090 | B9: TEXT | C9: text2 | D9: text2 | E9: =E8+1 -> 8 | G9: =$C9&"("&$B9&")" -> text2(TEXT) | H9: {}
A10: 0198ef6d-8543-b0f3-f8b0-c502bee720e9 | B10: ORGANIZATION | C10: org1 | D10: org1 | E10: =E9+1 -> 9 | G10: =$C10&"("&$B10&")" -> org1(ORGANIZATION) | H10: {}
A11: 0198ef6d-8543-5ea8-9f20-a8177b2d28d2 | B11: ORGANIZATION | C11: org2 | D11: org2 | E11: =E10+1 -> 10 | G11: =$C11&"("&$B11&")" -> org2(ORGANIZATION) | H11: {}
A12: 0198ef6d-8543-d4cb-e9cb-2c352f1baa30 | B12: GEO | C12: geo1 | D12: geo1 | E12: =E11+1 -> 11 | G12: =$C12&"("&$B12&")" -> geo1(GEO) | H12: {}
A13: 0198ef6d-8543-08a5-b8d2-bad85d28ce19 | B13: GEO | C13: geo2 | D13: geo2 | E13: =E12+1 -> 12 | G13: =$C13&"("&$B13&")" -> geo2(GEO) | H13: {}
A14: 0198ef6d-8543-090b-38ba-3d20aff20301 | B14: TIME | C14: time1 | D14: time1 | E14: =E13+1 -> 13 | G14: =$C14&"("&$B14&")" -> time1(TIME) | H14: {}
... A21: 0198ef6d-8543-4209-5045-1bdd507593a7 | B21: OTHER | C21: other2 | D21: other2 | E21: =E20+1 -> 20 | G21: =$C21&"("&$B21&")" -> other2(OTHER) | H21: {}

Sheet Col
A1: id | B1: dim_id | C1: dim_code | D1: code_suffix | E1: code | F1: rank_in_dim | G1: label | H1: col_type | I1: concept_set_id | J1: concept_set_name | K1: region_set_id | L1: region_set_name | M1: genetic_distance_protocol_id | N1: genetic_distance_protocol | O1: description | P1: props
A2: 0198ef6d-8543-eb2b-e8cd-6ad2e7ad4523 | B2: 0198ef6d-8543-8d7e-a786-a78961958b68 | C2: =INDEX(Dim!$C:$C,MATCH($B2,Dim!$A:$A,0)) -> nominal1 | D2: _1 | E2: =$C2&$D2 -> nominal1_1 | F2: =RIGHT($D2,LEN($D2)-1)+1-1 -> 1 | G2: =$E2 -> nominal1_1 | H2: NOMINAL | I2: 0198ef6d-8543-90a8-a647-ae05912c77ba | J2: =IF($I2="","",INDEX(ConceptSet!$C:$C,MATCH($I2,ConceptSet!$A:$A,0))) -> Nominal_1 | L2: =IF($K2="","",INDEX(RegionSet!$B:$B,MATCH($K2,RegionSet!$A:$A,0))) | O2: =$E2&" ("&$H2&(IF($J2="","",";"&$J2)&(IF($L2="","",";"&$L2)))&")" -> nominal1_1 (NOMINAL;Nominal_1) | P2: {}
A3: 0198ef6d-8543-1234-cbf1-9947a51d56ff | B3: 0198ef6d-8543-4e10-dadc-606a590cbf81 | C3: =INDEX(Dim!$C:$C,MATCH($B3,Dim!$A:$A,0)) -> nominal2 | D3: _1 | E3: =$C3&$D3 -> nominal2_1 | F3: =RIGHT($D3,LEN($D3)-1)+1-1 -> 1 | G3: =$E3 -> nominal2_1 | H3: NOMINAL | I3: 0198ef6d-8543-2a99-b3be-b0d2583cb604 | J3: =IF($I3="","",INDEX(ConceptSet!$C:$C,MATCH($I3,ConceptSet!$A:$A,0))) -> Nominal_2 | L3: =IF($K3="","",INDEX(RegionSet!$B:$B,MATCH($K3,RegionSet!$A:$A,0))) | O3: =$E3&" ("&$H3&(IF($J3="","",";"&$J3)&(IF($L3="","",";"&$L3)))&")" -> nominal2_1 (NOMINAL;Nominal_2) | P3: {}
A4: 0198ef6d-8543-50ea-8c7a-9f5c1a8041c4 | B4: 0198ef6d-8543-4b57-ccc7-1e34bcca2de1 | C4: =INDEX(Dim!$C:$C,MATCH($B4,Dim!$A:$A,0)) -> ordinal1 | D4: _1 | E4: =$C4&$D4 -> ordinal1_1 | F4: =RIGHT($D4,LEN($D4)-1)+1-1 -> 1 | G4: =$E4 -> ordinal1_1 | H4: ORDINAL | I4: 0198ef6d-8543-b279-03a6-da9684b42b08 | J4: =IF($I4="","",INDEX(ConceptSet!$C:$C,MATCH($I4,ConceptSet!$A:$A,0))) -> Ordinal_1 | L4: =IF($K4="","",INDEX(RegionSet!$B:$B,MATCH($K4,RegionSet!$A:$A,0))) | O4: =$E4&" ("&$H4&(IF($J4="","",";"&$J4)&(IF($L4="","",";"&$L4)))&")" -> ordinal1_1 (ORDINAL;Ordinal_1) | P4: {}
A5: 0198ef6d-8543-76c4-4fb4-25f7403d7972 | B5: 0198ef6d-8543-9c78-54a7-6b4c2ca6ce88 | C5: =INDEX(Dim!$C:$C,MATCH($B5,Dim!$A:$A,0)) -> ordinal2 | D5: _1 | E5: =$C5&$D5 -> ordinal2_1 | F5: =RIGHT($D5,LEN($D5)-1)+1-1 -> 1 | G5: =$E5 -> ordinal2_1 | H5: ORDINAL | I5: 0198ef6d-8543-d076-3da0-dd48921087f9 | J5: =IF($I5="","",INDEX(ConceptSet!$C:$C,MATCH($I5,ConceptSet!$A:$A,0))) -> Ordinal_2 | L5: =IF($K5="","",INDEX(RegionSet!$B:$B,MATCH($K5,RegionSet!$A:$A,0))) | O5: =$E5&" ("&$H5&(IF($J5="","",";"&$J5)&(IF($L5="","",";"&$L5)))&")" -> ordinal2_1 (ORDINAL;Ordinal_2) | P5: {}
A6: 0198ef6d-8543-479e-1e7a-3428fa97ebc7 | B6: 0198ef6d-8543-6a7f-4553-b7280cc2ab9b | C6: =INDEX(Dim!$C:$C,MATCH($B6,Dim!$A:$A,0)) -> regex1 | D6: _1 | E6: =$C6&$D6 -> regex1_1 | F6: =RIGHT($D6,LEN($D6)-1)+1-1 -> 1 | G6: =$E6 -> regex1_1 | H6: REGULAR_LANGUAGE | I6: 0198ef6d-8543-a151-ab47-0394a80e2a05 | J6: =IF($I6="","",INDEX(ConceptSet!$C:$C,MATCH($I6,ConceptSet!$A:$A,0))) -> Regex_1 | L6: =IF($K6="","",INDEX(RegionSet!$B:$B,MATCH($K6,RegionSet!$A:$A,0))) | O6: =$E6&" ("&$H6&(IF($J6="","",";"&$J6)&(IF($L6="","",";"&$L6)))&")" -> regex1_1 (REGULAR_LANGUAGE;Regex_1) | P6: {}
A7: 0198ef6d-8543-0924-3aca-6065227cd9ef | B7: 0198ef6d-8543-5e3c-cec3-8db0ccbd38fa | C7: =INDEX(Dim!$C:$C,MATCH($B7,Dim!$A:$A,0)) -> regex2 | D7: _1 | E7: =$C7&$D7 -> regex2_1 | F7: =RIGHT($D7,LEN($D7)-1)+1-1 -> 1 | G7: =$E7 -> regex2_1 | H7: REGULAR_LANGUAGE | I7: 0198ef6d-8543-6df8-9098-78280604c758 | J7: =IF($I7="","",INDEX(ConceptSet!$C:$C,MATCH($I7,ConceptSet!$A:$A,0))) -> Regex_2 | L7: =IF($K7="","",INDEX(RegionSet!$B:$B,MATCH($K7,RegionSet!$A:$A,0))) | O7: =$E7&" ("&$H7&(IF($J7="","",";"&$J7)&(IF($L7="","",";"&$L7)))&")" -> regex2_1 (REGULAR_LANGUAGE;Regex_2) | P7: {}
A8: 0198ef6d-8543-78ba-e607-ac65487d273b | B8: 0198ef6d-8543-0b52-87e5-431792f951a2 | C8: =INDEX(Dim!$C:$C,MATCH($B8,Dim!$A:$A,0)) -> text1 | D8: _1 | E8: =$C8&$D8 -> text1_1 | F8: =RIGHT($D8,LEN($D8)-1)+1-1 -> 1 | G8: =$E8 -> text1_1 | H8: TEXT | J8: =IF($I8="","",INDEX(ConceptSet!$C:$C,MATCH($I8,ConceptSet!$A:$A,0))) | L8: =IF($K8="","",INDEX(RegionSet!$B:$B,MATCH($K8,RegionSet!$A:$A,0))) | O8: =$E8&" ("&$H8&(IF($J8="","",";"&$J8)&(IF($L8="","",";"&$L8)))&")" -> text1_1 (TEXT) | P8: {}
A9: 0198ef6d-8543-2d1c-8ae5-fde6579f02e4 | B9: 0198ef6d-8543-e0a4-1718-6ae19c4f6090 | C9: =INDEX(Dim!$C:$C,MATCH($B9,Dim!$A:$A,0)) -> text2 | D9: _1 | E9: =$C9&$D9 -> text2_1 | F9: =RIGHT($D9,LEN($D9)-1)+1-1 -> 1 | G9: =$E9 -> text2_1 | H9: TEXT | J9: =IF($I9="","",INDEX(ConceptSet!$C:$C,MATCH($I9,ConceptSet!$A:$A,0))) | L9: =IF($K9="","",INDEX(RegionSet!$B:$B,MATCH($K9,RegionSet!$A:$A,0))) | O9: =$E9&" ("&$H9&(IF($J9="","",";"&$J9)&(IF($L9="","",";"&$L9)))&")" -> text2_1 (TEXT) | P9: {}
A10: 0198ef6d-8543-9c02-f715-88d1935aca9a | B10: 0198ef6d-8543-b0f3-f8b0-c502bee720e9 | C10: =INDEX(Dim!$C:$C,MATCH($B10,Dim!$A:$A,0)) -> org1 | D10: _1 | E10: =$C10&$D10 -> org1_1 | F10: =RIGHT($D10,LEN($D10)-1)+1-1 -> 1 | G10: =$E10 -> org1_1 | H10: ORGANIZATION | J10: =IF($I10="","",INDEX(ConceptSet!$C:$C,MATCH($I10,ConceptSet!$A:$A,0))) | L10: =IF($K10="","",INDEX(RegionSet!$B:$B,MATCH($K10,RegionSet!$A:$A,0))) | O10: =$E10&" ("&$H10&(IF($J10="","",";"&$J10)&(IF($L10="","",";"&$L10)))&")" -> org1_1 (ORGANIZATION) | P10: {}
A11: 0198ef6d-8543-5be8-beb1-cbc53a476302 | B11: 0198ef6d-8543-5ea8-9f20-a8177b2d28d2 | C11: =INDEX(Dim!$C:$C,MATCH($B11,Dim!$A:$A,0)) -> org2 | D11: _1 | E11: =$C11&$D11 -> org2_1 | F11: =RIGHT($D11,LEN($D11)-1)+1-1 -> 1 | G11: =$E11 -> org2_1 | H11: ORGANIZATION | J11: =IF($I11="","",INDEX(ConceptSet!$C:$C,MATCH($I11,ConceptSet!$A:$A,0))) | L11: =IF($K11="","",INDEX(RegionSet!$B:$B,MATCH($K11,RegionSet!$A:$A,0))) | O11: =$E11&" ("&$H11&(IF($J11="","",";"&$J11)&(IF($L11="","",";"&$L11)))&")" -> org2_1 (ORGANIZATION) | P11: {}
A12: 0198ef6d-8543-13b8-702c-f36c6968d08f | B12: 0198ef6d-8543-d4cb-e9cb-2c352f1baa30 | C12: =INDEX(Dim!$C:$C,MATCH($B12,Dim!$A:$A,0)) -> geo1 | D12: _1 | E12: =$C12&$D12 -> geo1_1 | F12: =RIGHT($D12,LEN($D12)-1)+1-1 -> 1 | G12: =$E12 -> geo1_1 | H12: GEO_REGION | J12: =IF($I12="","",INDEX(ConceptSet!$C:$C,MATCH($I12,ConceptSet!$A:$A,0))) | K12: 0198ef6d-8543-92bb-3d7b-9a6b17e52c7d | L12: =IF($K12="","",INDEX(RegionSet!$B:$B,MATCH($K12,RegionSet!$A:$A,0))) -> PC_L4 | O12: =$E12&" ("&$H12&(IF($J12="","",";"&$J12)&(IF($L12="","",";"&$L12)))&")" -> geo1_1 (GEO_REGION;PC_L4) | P12: {}
A13: 0198ef6d-8543-74d1-8cf2-4f5da375834f | B13: 0198ef6d-8543-d4cb-e9cb-2c352f1baa30 | C13: =INDEX(Dim!$C:$C,MATCH($B13,Dim!$A:$A,0)) -> geo1 | D13: _2 | E13: =$C13&$D13 -> geo1_2 | F13: =RIGHT($D13,LEN($D13)-1)+1-1 -> 2 | G13: =$E13 -> geo1_2 | H13: GEO_REGION | J13: =IF($I13="","",INDEX(ConceptSet!$C:$C,MATCH($I13,ConceptSet!$A:$A,0))) | K13: 0198ef6d-8543-0ad2-6a86-701cc690b0a4 | L13: =IF($K13="","",INDEX(RegionSet!$B:$B,MATCH($K13,RegionSet!$A:$A,0))) -> PC_L3 | O13: =$E13&" ("&$H13&(IF($J13="","",";"&$J13)&(IF($L13="","",";"&$L13)))&")" -> geo1_2 (GEO_REGION;PC_L3) | P13: {}
A14: 0198ef6d-8543-b7d9-c034-47ae7fb11c50 | B14: 0198ef6d-8543-d4cb-e9cb-2c352f1baa30 | C14: =INDEX(Dim!$C:$C,MATCH($B14,Dim!$A:$A,0)) -> geo1 | D14: _3 | E14: =$C14&$D14 -> geo1_3 | F14: =RIGHT($D14,LEN($D14)-1)+1-1 -> 3 | G14: =$E14 -> geo1_3 | H14: GEO_REGION | J14: =IF($I14="","",INDEX(ConceptSet!$C:$C,MATCH($I14,ConceptSet!$A:$A,0))) | K14: 0198ef6d-8543-5e3f-5ed0-dd932e32c2aa | L14: =IF($K14="","",INDEX(RegionSet!$B:$B,MATCH($K14,RegionSet!$A:$A,0))) -> MUN | O14: =$E14&" ("&$H14&(IF($J14="","",";"&$J14)&(IF($L14="","",";"&$L14)))&")" -> geo1_3 (GEO_REGION;MUN) | P14: {}
A15: 0198ef6d-8543-61aa-6bef-ab847c75d5f6 | B15: 0198ef6d-8543-d4cb-e9cb-2c352f1baa30 | C15: =INDEX(Dim!$C:$C,MATCH($B15,Dim!$A:$A,0)) -> geo1 | D15: _4 | E15: =$C15&$D15 -> geo1_4 | F15: =RIGHT($D15,LEN($D15)-1)+1-1 -> 4 | G15: =$E15 -> geo1_4 | H15: GEO_REGION | J15: =IF($I15="","",INDEX(ConceptSet!$C:$C,MATCH($I15,ConceptSet!$A:$A,0))) | K15: 0198ef6d-8543-ca21-8fc9-aac9c10fe055 | L15: =IF($K15="","",INDEX(RegionSet!$B:$B,MATCH($K15,RegionSet!$A:$A,0))) -> PV | O15: =$E15&" ("&$H15&(IF($J15="","",";"&$J15)&(IF($L15="","",";"&$L15)))&")" -> geo1_4 (GEO_REGION;PV) | P15: {}
A16: 0198ef6d-8543-c6b8-13b1-618c88c659c4 | B16: 0198ef6d-8543-08a5-b8d2-bad85d28ce19 | C16: =INDEX(Dim!$C:$C,MATCH($B16,Dim!$A:$A,0)) -> geo2 | D16: _1 | E16: =$C16&$D16 -> geo2_1 | F16: =RIGHT($D16,LEN($D16)-1)+1-1 -> 1 | G16: =$E16 -> geo2_1 | H16: GEO_REGION | J16: =IF($I16="","",INDEX(ConceptSet!$C:$C,MATCH($I16,ConceptSet!$A:$A,0))) | K16: 0198ef6d-8543-92bb-3d7b-9a6b17e52c7d | L16: =IF($K16="","",INDEX(RegionSet!$B:$B,MATCH($K16,RegionSet!$A:$A,0))) -> PC_L4 | O16: =$E16&" ("&$H16&(IF($J16="","",";"&$J16)&(IF($L16="","",";"&$L16)))&")" -> geo2_1 (GEO_REGION;PC_L4) | P16: {}
A17: 0198ef6d-8543-1f4e-e4ff-26b349afa1da | B17: 0198ef6d-8543-08a5-b8d2-bad85d28ce19 | C17: =INDEX(Dim!$C:$C,MATCH($B17,Dim!$A:$A,0)) -> geo2 | D17: _2 | E17: =$C17&$D17 -> geo2_2 | F17: =RIGHT($D17,LEN($D17)-1)+1-1 -> 2 | G17: =$E17 -> geo2_2 | H17: GEO_REGION | J17: =IF($I17="","",INDEX(ConceptSet!$C:$C,MATCH($I17,ConceptSet!$A:$A,0))) | K17: 0198ef6d-8543-0ad2-6a86-701cc690b0a4 | L17: =IF($K17="","",INDEX(RegionSet!$B:$B,MATCH($K17,RegionSet!$A:$A,0))) -> PC_L3 | O17: =$E17&" ("&$H17&(IF($J17="","",";"&$J17)&(IF($L17="","",";"&$L17)))&")" -> geo2_2 (GEO_REGION;PC_L3) | P17: {}
A18: 0198ef6d-8543-1d52-5bac-f77d1900a8dd | B18: 0198ef6d-8543-08a5-b8d2-bad85d28ce19 | C18: =INDEX(Dim!$C:$C,MATCH($B18,Dim!$A:$A,0)) -> geo2 | D18: _3 | E18: =$C18&$D18 -> geo2_3 | F18: =RIGHT($D18,LEN($D18)-1)+1-1 -> 3 | G18: =$E18 -> geo2_3 | H18: GEO_REGION | J18: =IF($I18="","",INDEX(ConceptSet!$C:$C,MATCH($I18,ConceptSet!$A:$A,0))) | K18: 0198ef6d-8543-5e3f-5ed0-dd932e32c2aa | L18: =IF($K18="","",INDEX(RegionSet!$B:$B,MATCH($K18,RegionSet!$A:$A,0))) -> MUN | O18: =$E18&" ("&$H18&(IF($J18="","",";"&$J18)&(IF($L18="","",";"&$L18)))&")" -> geo2_3 (GEO_REGION;MUN) | P18: {}
A19: 0198ef6d-8543-d807-f0b2-816adb66b0e2 | B19: 0198ef6d-8543-08a5-b8d2-bad85d28ce19 | C19: =INDEX(Dim!$C:$C,MATCH($B19,Dim!$A:$A,0)) -> geo2 | D19: _4 | E19: =$C19&$D19 -> geo2_4 | F19: =RIGHT($D19,LEN($D19)-1)+1-1 -> 4 | G19: =$E19 -> geo2_4 | H19: GEO_REGION | J19: =IF($I19="","",INDEX(ConceptSet!$C:$C,MATCH($I19,ConceptSet!$A:$A,0))) | K19: 0198ef6d-8543-ca21-8fc9-aac9c10fe055 | L19: =IF($K19="","",INDEX(RegionSet!$B:$B,MATCH($K19,RegionSet!$A:$A,0))) -> PV | O19: =$E19&" ("&$H19&(IF($J19="","",";"&$J19)&(IF($L19="","",";"&$L19)))&")" -> geo2_4 (GEO_REGION;PV) | P19: {}
