Workbook

Sheet Organization
A1: id | B1: name | C1: legal_entity_code | D1: legal_region_id | E1: legal_region
A2: 018d074d-ea0c-e942-07db-a3cc0ba1d653 | B2: org1 | C2: org1
A3: 0195d18c-1c92-0ed4-2e94-b4f66d82baf3 | B3: org2 | C3: org2
A4: 0195d18c-1c92-52b3-93e0-43dc1f2aa037 | B4: org3 | C4: org3
A5: 0195d18c-1c92-d419-4c71-a570f428499b | B5: org4 | C5: org4
A6: 0195d18c-1c93-02a2-6920-7e4dbfb73ce0 | B6: org5 | C6: org5

Sheet DataCollection
A1: id | B1: name | C1: description
A2: 0195d18c-1ca2-a23d-1f64-00271f63199c | B2: data_collection1 | C2: ="dc"&RIGHT($B2,LEN($B2)-15) -> dc1
A3: 0195d18c-1ca2-2a29-96a5-37c6bf87f586 | B3: data_collection2 | C3: ="dc"&RIGHT($B3,LEN($B3)-15) -> dc2
A4: 0195d18c-1ca2-3a4f-1878-fbe3282c9c76 | B4: data_collection3 | C4: ="dc"&RIGHT($B4,LEN($B4)-15) -> dc3
A5: 0195d18c-1ca2-e55a-608d-a42fc6f948e1 | B5: data_collection4 | C5: ="dc"&RIGHT($B5,LEN($B5)-15) -> dc4
A6: 0195d18c-1ca2-b728-a2a1-d2a4cf7b8eb8 | B6: data_collection5 | C6: ="dc"&RIGHT($B6,LEN($B6)-15) -> dc5
A7: 0195d18c-1ca3-f309-f6f1-e4807afe3802 | B7: data_collection6 | C7: ="dc"&RIGHT($B7,LEN($B7)-15) -> dc6
A8: 0195d18c-1ca3-db40-a2a8-6dc905d6c1e9 | B8: data_collection7 | C8: ="dc"&RIGHT($B8,LEN($B8)-15) -> dc7
A9: 0195d18c-1ca3-da0a-44bb-877b3a1eb73e | B9: data_collection8 | C9: ="dc"&RIGHT($B9,LEN($B9)-15) -> dc8
A10: 0195d18c-1ca3-4d34-d0e9-8f024ad8651a | B10: data_collection9 | C10: ="dc"&RIGHT($B10,LEN($B10)-15) -> dc9
A11: 0195d18c-1ca3-11a2-bf20-8eaaa09cc070 | B11: data_collection10 | C11: ="dc"&RIGHT($B11,LEN($B11)-15) -> dc10
A12: 0195d18c-1ca4-e691-7ebd-8ecb1a16a2ed | B12: data_collection11 | C12: ="dc"&RIGHT($B12,LEN($B12)-15) -> dc11

Sheet User
A1: id | B1: key | C1: email | D1: name | E1: is_active | F1: roles | G1: organization_id | H1: dm.organization.name | I1: dm.roles.is_root | J1: dm.roles.is_app_admin | K1: dm.roles.is_refdata_admin | L1: dm.roles.is_org_user | M1: dm.is_ge_app_admin
A2: 019542cc-8225-8f5d-fa30-d9c3f2629703 | B2: root1_1@org1.org | C2: root1_1@org1.org | D2: =LEFT(C2,FIND("@",C2)-1) -> root1_1 | E2: TRUE | F2: ["CASEDB_ROOT"] | G2: 018d074d-ea0c-e942-07db-a3cc0ba1d653 | H2: =INDEX(Organization!$B:$B,MATCH($G2,Organization!$A:$A,0)) -> org1 | I2: =ISNUMBER(SEARCH("ROOT", F2)) -> TRUE | J2: =ISNUMBER(SEARCH("APP_ADMIN", $F2)) -> FALSE | K2: =ISNUMBER(SEARCH("METADATA_ADMIN", $F2)) -> FALSE | L2: =ISNUMBER(SEARCH("ORG_USER", $F2)) -> FALSE | M2: =OR($I2,$J2) -> TRUE
A3: 0195d18c-1c92-110e-81c1-75ba0fec4494 | B3: app_admin1_1@org1.org | C3: app_admin1_1@org1.org | D3: =LEFT(C3,FIND("@",C3)-1) -> app_admin1_1 | E3: TRUE | F3: ["CASEDB_APP_ADMIN"] | G3: 018d074d-ea0c-e942-07db-a3cc0ba1d653 | H3: =INDEX(Organization!$B:$B,MATCH($G3,Organization!$A:$A,0)) -> org1 | I3: =ISNUMBER(SEARCH("ROOT", F3)) -> FALSE | J3: =ISNUMBER(SEARCH("APP_ADMIN", $F3)) -> TRUE | K3: =ISNUMBER(SEARCH("METADATA_ADMIN", $F3)) -> FALSE | L3: =ISNUMBER(SEARCH("ORG_USER", $F3)) -> FALSE | M3: =OR($I3,$J3) -> TRUE
A4: 0195d18c-1c93-bcbb-eea8-94332d77b172 | B4: refdata_admin1_1@org1.org | C4: refdata_admin1_1@org1.org | D4: =LEFT(C4,FIND("@",C4)-1) -> refdata_admin1_1 | E4: TRUE | F4: ["CASEDB_REFDATA_ADMIN"] | G4: 018d074d-ea0c-e942-07db-a3cc0ba1d653 | H4: =INDEX(Organization!$B:$B,MATCH($G4,Organization!$A:$A,0)) -> org1 | I4: =ISNUMBER(SEARCH("ROOT", F4)) -> FALSE | J4: =ISNUMBER(SEARCH("APP_ADMIN", $F4)) -> FALSE | K4: =ISNUMBER(SEARCH("METADATA_ADMIN", $F4)) -> FALSE | L4: =ISNUMBER(SEARCH("ORG_USER", $F4)) -> FALSE | M4: =OR($I4,$J4) -> FALSE
A5: 0195d18c-1c93-1f4b-8c40-19223d6c7a8c | B5: org_admin1_1@org1.org | C5: org_admin1_1@org1.org | D5: =LEFT(C5,FIND("@",C5)-1) -> org_admin1_1 | E5: TRUE | F5: ["CASEDB_ORG_ADMIN"] | G5: 018d074d-ea0c-e942-07db-a3cc0ba1d653 | H5: =INDEX(Organization!$B:$B,MATCH($G5,Organization!$A:$A,0)) -> org1 | I5: =ISNUMBER(SEARCH("ROOT", F5)) -> FALSE | J5: =ISNUMBER(SEARCH("APP_ADMIN", $F5)) -> FALSE | K5: =ISNUMBER(SEARCH("METADATA_ADMIN", $F5)) -> FALSE | L5: =ISNUMBER(SEARCH("ORG_USER", $F5)) -> FALSE | M5: =OR($I5,$J5) -> FALSE
A6: 0195d18c-1c95-2343-576e-0c14e0a4505d | B6: org_admin2_1@org2.org | C6: org_admin2_1@org2.org | D6: =LEFT(C6,FIND("@",C6)-1) -> org_admin2_1 | E6: TRUE | F6: ["CASEDB_ORG_ADMIN"] | G6: 0195d18c-1c92-0ed4-2e94-b4f66d82baf3 | H6: =INDEX(Organization!$B:$B,MATCH($G6,Organization!$A:$A,0)) -> org2 | I6: =ISNUMBER(SEARCH("ROOT", F6)) -> FALSE | J6: =ISNUMBER(SEARCH("APP_ADMIN", $F6)) -> FALSE | K6: =ISNUMBER(SEARCH("METADATA_ADMIN", $F6)) -> FALSE | L6: =ISNUMBER(SEARCH("ORG_USER", $F6)) -> FALSE | M6: =OR($I6,$J6) -> FALSE
A7: 0195d18c-1c96-59a8-d2a6-70a3b13175a1 | B7: org_admin3_1@org3.org | C7: org_admin3_1@org3.org | D7: =LEFT(C7,FIND("@",C7)-1) -> org_admin3_1 | E7: TRUE | F7: ["CASEDB_ORG_ADMIN"] | G7: 0195d18c-1c92-52b3-93e0-43dc1f2aa037 | H7: =INDEX(Organization!$B:$B,MATCH($G7,Organization!$A:$A,0)) -> org3 | I7: =ISNUMBER(SEARCH("ROOT", F7)) -> FALSE | J7: =ISNUMBER(SEARCH("APP_ADMIN", $F7)) -> FALSE | K7: =ISNUMBER(SEARCH("METADATA_ADMIN", $F7)) -> FALSE | L7: =ISNUMBER(SEARCH("ORG_USER", $F7)) -> FALSE | M7: =OR($I7,$J7) -> FALSE
A8: 0195d18c-1c96-08ed-1241-eaf327bd1ffc | B8: org_admin4_1@org4.org | C8: org_admin4_1@org4.org | D8: =LEFT(C8,FIND("@",C8)-1) -> org_admin4_1 | E8: TRUE | F8: ["CASEDB_ORG_ADMIN"] | G8: 0195d18c-1c92-d419-4c71-a570f428499b | H8: =INDEX(Organization!$B:$B,MATCH($G8,Organization!$A:$A,0)) -> org4 | I8: =ISNUMBER(SEARCH("ROOT", F8)) -> FALSE | J8: =ISNUMBER(SEARCH("APP_ADMIN", $F8)) -> FALSE | K8: =ISNUMBER(SEARCH("METADATA_ADMIN", $F8)) -> FALSE | L8: =ISNUMBER(SEARCH("ORG_USER", $F8)) -> FALSE | M8: =OR($I8,$J8) -> FALSE
A9: 0195d18c-1c97-faac-82eb-3e357979b402 | B9: org_admin5_1@org5.org | C9: org_admin5_1@org5.org | D9: =LEFT(C9,FIND("@",C9)-1) -> org_admin5_1 | E9: TRUE | F9: ["CASEDB_ORG_ADMIN"] | G9: 0195d18c-1c93-02a2-6920-7e4dbfb73ce0 | H9: =INDEX(Organization!$B:$B,MATCH($G9,Organization!$A:$A,0)) -> org5 | I9: =ISNUMBER(SEARCH("ROOT", F9)) -> FALSE | J9: =ISNUMBER(SEARCH("APP_ADMIN", $F9)) -> FALSE | K9: =ISNUMBER(SEARCH("METADATA_ADMIN", $F9)) -> FALSE | L9: =ISNUMBER(SEARCH("ORG_USER", $F9)) -> FALSE | M9: =OR($I9,$J9) -> FALSE
A10: 0195d18c-1c98-7e0b-0c91-8cafbdb2c852 | B10: org_user1_1@org1.org | C10: org_user1_1@org1.org | D10: =LEFT(C10,FIND("@",C10)-1) -> org_user1_1 | E10: TRUE | F10: ["CASEDB_ORG_USER"] | G10: 018d074d-ea0c-e942-07db-a3cc0ba1d653 | H10: =INDEX(Organization!$B:$B,MATCH($G10,Organization!$A:$A,0)) -> org1 | I10: =ISNUMBER(SEARCH("ROOT", F10)) -> FALSE | J10: =ISNUMBER(SEARCH("APP_ADMIN", $F10)) -> FALSE | K10: =ISNUMBER(SEARCH("METADATA_ADMIN", $F10)) -> FALSE | L10: =ISNUMBER(SEARCH("ORG_USER", $F10)) -> TRUE | M10: =OR($I10,$J10) -> FALSE
A11: 0195d18c-1c98-5a1e-55b9-67b877813693 | B11: org_user1_2@org1.org | C11: org_user1_2@org1.org | D11: =LEFT(C11,FIND("@",C11)-1) -> org_user1_2 | E11: TRUE | F11: ["CASEDB_ORG_USER"] | G11: 018d074d-ea0c-e942-07db-a3cc0ba1d653 | H11: =INDEX(Organization!$B:$B,MATCH($G11,Organization!$A:$A,0)) -> org1 | I11: =ISNUMBER(SEARCH("ROOT", F11)) -> FALSE | J11: =ISNUMBER(SEARCH("APP_ADMIN", $F11)) -> FALSE | K11: =ISNUMBER(SEARCH("METADATA_ADMIN", $F11)) -> FALSE | L11: =ISNUMBER(SEARCH("ORG_USER", $F11)) -> TRUE | M11: =OR($I11,$J11) -> FALSE
A12: 0195d18c-1c99-03eb-f1b4-a88daae1b74c | B12: org_user1_3@org1.org | C12: org_user1_3@org1.org | D12: =LEFT(C12,FIND("@",C12)-1) -> org_user1_3 | E12: TRUE | F12: ["CASEDB_ORG_USER"] | G12: 018d074d-ea0c-e942-07db-a3cc0ba1d653 | H12: =INDEX(Organization!$B:$B,MATCH($G12,Organization!$A:$A,0)) -> org1 | I12: =ISNUMBER(SEARCH("ROOT", F12)) -> FALSE | J12: =ISNUMBER(SEARCH("APP_ADMIN", $F12)) -> FALSE | K12: =ISNUMBER(SEARCH("METADATA_ADMIN", $F12)) -> FALSE | L12: =ISNUMBER(SEARCH("ORG_USER", $F12)) -> TRUE | M12: =OR($I12,$J12) -> FALSE
A13: 0195d18c-1c99-a68b-99dd-a489908e8df1 | B13: org_user1_4@org1.org | C13: org_user1_4@org1.org | D13: =LEFT(C13,FIND("@",C13)-1) -> org_user1_4 | E13: TRUE | F13: ["CASEDB_ORG_USER"] | G13: 018d074d-ea0c-e942-07db-a3cc0ba1d653 | H13: =INDEX(Organization!$B:$B,MATCH($G13,Organization!$A:$A,0)) -> org1 | I13: =ISNUMBER(SEARCH("ROOT", F13)) -> FALSE | J13: =ISNUMBER(SEARCH("APP_ADMIN", $F13)) -> FALSE | K13: =ISNUMBER(SEARCH("METADATA_ADMIN", $F13)) -> FALSE | L13: =ISNUMBER(SEARCH("ORG_USER", $F13)) -> TRUE | M13: =OR($I13,$J13) -> FALSE
... A29: 0195d18c-1ca1-d3df-24f3-7aac91cc3f3a | B29: org_user5_4@org5.org | C29: org_user5_4@org5.org | D29: =LEFT(C29,FIND("@",C29)-1) -> org_user5_4 | E29: TRUE | F29: ["CASEDB_ORG_USER"] | G29: 0195d18c-1c93-02a2-6920-7e4dbfb73ce0 | H29: =INDEX(Organization!$B:$B,MATCH($G29,Organization!$A:$A,0)) -> org5 | I29: =ISNUMBER(SEARCH("ROOT", F29)) -> FALSE | J29: =ISNUMBER(SEARCH("APP_ADMIN", $F29)) -> FALSE | K29: =ISNUMBER(SEARCH("METADATA_ADMIN", $F29)) -> FALSE | L29: =ISNUMBER(SEARCH("ORG_USER", $F29)) -> TRUE | M29: =OR($I29,$J29) -> FALSE

Sheet UserInvitation
A1: id | B1: key | C1: email | D1: dm.name | E1: token | F1: expires_at | G1: roles | H1: invited_by_user_id | I1: dm.invited_by_user | J1: organization_id | K1: dm.organization
A2: 0195d18c-1c91-417d-6686-2f6cb5ff95b9 | B2: app_admin1_1@org1.org | C2: app_admin1_1@org1.org | D2: =LEFT($C2,LEN($C2)-9) -> app_admin1_1 | E2: 26dcbff8-2925-4078-90ad-bbe74165f6b3 | F2: 45743.391 | G2: ["APP_ADMIN"] | H2: 019542cc-8225-8f5d-fa30-d9c3f2629703 | I2: =INDEX(User!$D:$D,MATCH($H2,User!$A:$A,0)) -> root1_1 | J2: 018d074d-ea0c-e942-07db-a3cc0ba1d653 | K2: =INDEX(Organization!$B:$B,MATCH($J2,Organization!$A:$A,0)) -> org1
A3: 0195d18c-1c93-6939-20ec-9c4c00d851c1 | B3: refdata_admin1_1@org1.org | C3: refdata_admin1_1@org1.org | D3: =LEFT($C3,LEN($C3)-9) -> refdata_admin1_1 | E3: 10ad47a6-0901-408c-bfc0-a05a4e83af4e | F3: 45743.391 | G3: ["REFDATA_ADMIN"] | H3: 0195d18c-1c92-110e-81c1-75ba0fec4494 | I3: =INDEX(User!$D:$D,MATCH($H3,User!$A:$A,0)) -> app_admin1_1 | J3: 018d074d-ea0c-e942-07db-a3cc0ba1d653 | K3: =INDEX(Organization!$B:$B,MATCH($J3,Organization!$A:$A,0)) -> org1
A4: 0195d18c-1c93-ec90-9271-1015b282d4b3 | B4: org_admin1_1@org1.org | C4: org_admin1_1@org1.org | D4: =LEFT($C4,LEN($C4)-9) -> org_admin1_1 | E4: 6f8d5681-2c6c-44ae-9522-178a45deaf16 | F4: 45743.391 | G4: ["ORG_ADMIN"] | H4: 0195d18c-1c92-110e-81c1-75ba0fec4494 | I4: =INDEX(User!$D:$D,MATCH($H4,User!$A:$A,0)) -> app_admin1_1 | J4: 018d074d-ea0c-e942-07db-a3cc0ba1d653 | K4: =INDEX(Organization!$B:$B,MATCH($J4,Organization!$A:$A,0)) -> org1
A5: 0195d18c-1c95-0879-fcf0-17e1131cc29b | B5: org_admin2_1@org2.org | C5: org_admin2_1@org2.org | D5: =LEFT($C5,LEN($C5)-9) -> org_admin2_1 | E5: 839e81a3-3184-4c47-bf1c-7f1f964fe280 | F5: 45743.391 | G5: ["ORG_ADMIN"] | H5: 0195d18c-1c92-110e-81c1-75ba0fec4494 | I5: =INDEX(User!$D:$D,MATCH($H5,User!$A:$A,0)) -> app_admin1_1 | J5: 0195d18c-1c92-0ed4-2e94-b4f66d82baf3 | K5: =INDEX(Organization!$B:$B,MATCH($J5,Organization!$A:$A,0)) -> org2
A6: 0195d18c-1c95-a854-581f-4e9ae9d85b92 | B6: org_admin3_1@org3.org | C6: org_admin3_1@org3.org | D6: =LEFT($C6,LEN($C6)-9) -> org_admin3_1 | E6: 1ad1489c-d661-475a-958d-c6684f5dd5d2 | F6: 45743.391 | G6: ["ORG_ADMIN"] | H6: 0195d18c-1c92-110e-81c1-75ba0fec4494 | I6: =INDEX(User!$D:$D,MATCH($H6,User!$A:$A,0)) -> app_admin1_1 | J6: 0195d18c-1c92-52b3-93e0-43dc1f2aa037 | K6: =INDEX(Organization!$B:$B,MATCH($J6,Organization!$A:$A,0)) -> org3
A7: 0195d18c-1c96-ec9c-d51d-0eec040d7ffd | B7: org_admin4_1@org4.org | C7: org_admin4_1@org4.org | D7: =LEFT($C7,LEN($C7)-9) -> org_admin4_1 | E7: ac3ef8cf-b738-458a-9250-e68a9452546b | F7: 45743.391 | G7: ["ORG_ADMIN"] | H7: 0195d18c-1c92-110e-81c1-75ba0fec4494 | I7: =INDEX(User!$D:$D,MATCH($H7,User!$A:$A,0)) -> app_admin1_1 | J7: 0195d18c-1c92-d419-4c71-a570f428499b | K7: =INDEX(Organization!$B:$B,MATCH($J7,Organization!$A:$A,0)) -> org4
A8: 0195d18c-1c97-bf94-f109-505bfb986995 | B8: org_admin5_1@org5.org | C8: org_admin5_1@org5.org | D8: =LEFT($C8,LEN($C8)-9) -> org_admin5_1 | E8: 2a653a89-2320-41a9-8163-356114c3ba28 | F8: 45743.391 | G8: ["ORG_ADMIN"] | H8: 0195d18c-1c92-110e-81c1-75ba0fec4494 | I8: =INDEX(User!$D:$D,MATCH($H8,User!$A:$A,0)) -> app_admin1_1 | J8: 0195d18c-1c93-02a2-6920-7e4dbfb73ce0 | K8: =INDEX(Organization!$B:$B,MATCH($J8,Organization!$A:$A,0)) -> org5
A9: 0195d18c-1c98-4085-5812-4a69516f59ae | B9: org_user1_1@org1.org | C9: org_user1_1@org1.org | D9: =LEFT($C9,LEN($C9)-9) -> org_user1_1 | E9: feb33345-6e94-4f64-807e-c8f4a6e9e232 | F9: 45743.391 | G9: ["ORG_USER"] | H9: 0195d18c-1c92-110e-81c1-75ba0fec4494 | I9: =INDEX(User!$D:$D,MATCH($H9,User!$A:$A,0)) -> app_admin1_1 | J9: 018d074d-ea0c-e942-07db-a3cc0ba1d653 | K9: =INDEX(Organization!$B:$B,MATCH($J9,Organization!$A:$A,0)) -> org1
A10: 0195d18c-1c98-91f0-72bb-c9c9bbd287c5 | B10: org_user1_2@org1.org | C10: org_user1_2@org1.org | D10: =LEFT($C10,LEN($C10)-9) -> org_user1_2 | E10: e2049ab9-9249-4847-852a-6b43b8d12ff8 | F10: 45743.391 | G10: ["ORG_USER"] | H10: 0195d18c-1c92-110e-81c1-75ba0fec4494 | I10: =INDEX(User!$D:$D,MATCH($H10,User!$A:$A,0)) -> app_admin1_1 | J10: 018d074d-ea0c-e942-07db-a3cc0ba1d653 | K10: =INDEX(Organization!$B:$B,MATCH($J10,Organization!$A:$A,0)) -> org1
A11: 0195d18c-1c98-90fe-f86a-b3ff952dc368 | B11: org_user1_3@org1.org | C11: org_user1_3@org1.org | D11: =LEFT($C11,LEN($C11)-9) -> org_user1_3 | E11: 973418bc-df76-4c74-bf1f-8919b9295848 | F11: 45743.391 | G11: ["ORG_USER"] | H11: 0195d18c-1c92-110e-81c1-75ba0fec4494 | I11: =INDEX(User!$D:$D,MATCH($H11,User!$A:$A,0)) -> app_admin1_1 | J11: 018d074d-ea0c-e942-07db-a3cc0ba1d653 | K11: =INDEX(Organization!$B:$B,MATCH($J11,Organization!$A:$A,0)) -> org1
A12: 0195d18c-1c99-b943-3900-1de44aa64da4 | B12: org_user1_4@org1.org | C12: org_user1_4@org1.org | D12: =LEFT($C12,LEN($C12)-9) -> org_user1_4 | E12: b9782553-9cf2-4fa6-9ad4-aae54307d988 | F12: 45743.391 | G12: ["ORG_USER"] | H12: 0195d18c-1c92-110e-81c1-75ba0fec4494 | I12: =INDEX(User!$D:$D,MATCH($H12,User!$A:$A,0)) -> app_admin1_1 | J12: 018d074d-ea0c-e942-07db-a3cc0ba1d653 | K12: =INDEX(Organization!$B:$B,MATCH($J12,Organization!$A:$A,0)) -> org1
A13: 0195d18c-1c99-ee95-2cb4-c932da0954b7 | B13: org_user2_1@org2.org | C13: org_user2_1@org2.org | D13: =LEFT($C13,LEN($C13)-9) -> org_user2_1 | E13: a3c4d7fd-06b7-43b7-bdfa-0cb99f4d15db | F13: 45743.391 | G13: ["ORG_USER"] | H13: 0195d18c-1c92-110e-81c1-75ba0fec4494 | I13: =INDEX(User!$D:$D,MATCH($H13,User!$A:$A,0)) -> app_admin1_1 | J13: 0195d18c-1c92-0ed4-2e94-b4f66d82baf3 | K13: =INDEX(Organization!$B:$B,MATCH($J13,Organization!$A:$A,0)) -> org2
... A28: 0195d18c-1ca1-507d-514e-7f6784ab639e | B28: org_user5_4@org5.org | C28: org_user5_4@org5.org | D28: =LEFT($C28,LEN($C28)-9) -> org_user5_4 | E28: 2ee7a962-2bc6-4e19-adad-f0c7597a075b | F28: 45743.391 | G28: ["ORG_USER"] | H28: 0195d18c-1c92-110e-81c1-75ba0fec4494 | I28: =INDEX(User!$D:$D,MATCH($H28,User!$A:$A,0)) -> app_admin1_1 | J28: 0195d18c-1c93-02a2-6920-7e4dbfb73ce0 | K28: =INDEX(Organization!$B:$B,MATCH($J28,Organization!$A:$A,0)) -> org5

Sheet Dim
A1: id | B1: dim_type | C1: code | D1: label | E1: rank | F1: col_code_prefix | G1: description | H1: props
A2: 0195d18c-1ca7-84a9-0f3d-1b864b527120 | B2: TEXT | C2: 1 | D2: dim1 | G2: ="dim"&$C2&"("&$B2&")" -> dim1(TEXT) | H2: {}
A3: 0195d18c-1ca7-eac1-1845-3de69c9879f2 | B3: TEXT | C3: 2 | D3: dim2 | G3: ="dim"&$C3&"("&$B3&")" -> dim2(TEXT) | H3: {}
A4: 0195d18c-1ca8-d12f-d2f7-05baa1ed8610 | B4: TEXT | C4: 3 | D4: dim3 | G4: ="dim"&$C4&"("&$B4&")" -> dim3(TEXT) | H4: {}

Sheet Col
A1: id | B1: dim_id | C1: dim | D1: code_suffix | E1: code | F1: rank_in_dim | G1: label | H1: col_type | I1: concept_set_id | J1: concept_set | K1: region_set_id | L1: region_set | M1: genetic_distance_protocol_id | N1: genetic_distance_protocol | O1: description | P1: props
A2: 0195d18c-1ca8-0d1d-088c-b8af029e62d9 | B2: 0195d18c-1ca7-84a9-0f3d-1b864b527120 | E2: 1_1 | F2: 1 | G2: dim1_1_text | H2: TEXT | O2: ="col"&$E2&"("&$H2&")" -> col1_1(TEXT) | P2: {}
A3: 0195d18c-1ca8-2d41-3f8a-a08c6c72781c | B3: 0195d18c-1ca7-84a9-0f3d-1b864b527120 | E3: 1_2 | F3: 2 | G3: dim1_2_text | H3: TEXT | O3: ="col"&$E3&"("&$H3&")" -> col1_2(TEXT) | P3: {}
A4: 0195d18c-1ca9-5de7-c726-bbac813384cb | B4: 0195d18c-1ca7-84a9-0f3d-1b864b527120 | E4: 1_3 | F4: 3 | G4: dim1_3_text | H4: TEXT | O4: ="col"&$E4&"("&$H4&")" -> col1_3(TEXT) | P4: {}
A5: 0195d18c-1ca9-79ee-762e-93e2d841f46e | B5: 0195d18c-1ca7-eac1-1845-3de69c9879f2 | E5: 2_1 | F5: 1 | G5: dim2_1_text | H5: TEXT | O5: ="col"&$E5&"("&$H5&")" -> col2_1(TEXT) | P5: {}
A6: 0195d18c-1ca9-e6f0-c3d1-2695fe9f64f9 | B6: 0195d18c-1ca7-eac1-1845-3de69c9879f2 | E6: 2_2 | F6: 2 | G6: dim2_2_text | H6: TEXT | O6: ="col"&$E6&"("&$H6&")" -> col2_2(TEXT) | P6: {}
A7: 0195d18c-1ca9-ec62-d071-2b041d96f2c7 | B7: 0195d18c-1ca7-eac1-1845-3de69c9879f2 | E7: 2_3 | F7: 3 | G7: dim2_3_text | H7: TEXT | O7: ="col"&$E7&"("&$H7&")" -> col2_3(TEXT) | P7: {}
A8: 0195d18c-1ca9-2301-2c4f-a4762f675f45 | B8: 0195d18c-1ca8-d12f-d2f7-05baa1ed8610 | E8: 3_1 | F8: 1 | G8: dim3_1_text | H8: TEXT | O8: ="col"&$E8&"("&$H8&")" -> col3_1(TEXT) | P8: {}
A9: 0195d18c-1caa-e67f-100d-0d313ce91422 | B9: 0195d18c-1ca8-d12f-d2f7-05baa1ed8610 | E9: 3_2 | F9: 2 | G9: dim3_2_text | H9: TEXT | O9: ="col"&$E9&"("&$H9&")" -> col3_2(TEXT) | P9: {}
A10: 0195d18c-1caa-aad7-3b8b-2357d679761c | B10: 0195d18c-1ca8-d12f-d2f7-05baa1ed8610 | E10: 3_3 | F10: 3 | G10: dim3_3_text | H10: TEXT | O10: ="col"&$E10&"("&$H10&")" -> col3_3(TEXT) | P10: {}

Sheet Disease
A1: id | B1: name | C1: icd_code
A2: 0195d18c-1ca4-6d4f-99b8-10458cd57f32 | B2: disease1
A3: 0195d18c-1ca4-2098-2e1c-1f2c2d58cd41 | B3: disease2
A4: 0195d18c-1ca4-9f3c-a017-a8f11202fb1c | B4: disease3
A5: 0195d18c-1ca4-86bf-f4e7-8c2a92ff370d | B5: disease4
A6: 0195d18c-1ca4-6a53-af25-e4cd2ea0545a | B6: disease5

Sheet EtiologicalAgent
A1: id | B1: name | C1: type
A2: 0195d18c-1ca4-82bc-c40f-054b28401ddd | B2: etiological_agent1 | C2: ORGANISM
A3: 0195d18c-1ca4-d963-1fbd-e9bf6dbb100c | B3: etiological_agent2 | C3: ORGANISM
A4: 0195d18c-1ca5-5802-0739-33f87df230d4 | B4: etiological_agent3 | C4: ORGANISM
A5: 0195d18c-1ca5-6d25-b2ad-a663425c8c15 | B5: etiological_agent4 | C5: ORGANISM
A6: 0195d18c-1ca5-49ab-b2c2-6e8556234b5c | B6: etiological_agent5 | C6: ORGANISM

Sheet CaseType
A1: id | B1: name | C1: description | D1: disease_id | E1: dm.disease.name | F1: disease | G1: etiological_agent_id | H1: dm.etiological_agent.name | I1: etiological_agent
A2: 0195d18c-1ca6-fd99-9d76-fcfa0c0cf400 | B2: case_type1 | D2: 0195d18c-1ca4-6d4f-99b8-10458cd57f32 | E2: =INDEX(Disease!$B:$B,MATCH($D2,Disease!$A:$A,0)) -> disease1 | G2: 0195d18c-1ca4-82bc-c40f-054b28401ddd | H2: =INDEX(EtiologicalAgent!$B:$B,MATCH($G2,EtiologicalAgent!$A:$A,0)) -> etiological_agent1
A3: 0195d18c-1ca6-752a-ec56-ed1b3d0cb095 | B3: case_type2 | D3: 0195d18c-1ca4-2098-2e1c-1f2c2d58cd41 | E3: =INDEX(Disease!$B:$B,MATCH($D3,Disease!$A:$A,0)) -> disease2 | G3: 0195d18c-1ca4-d963-1fbd-e9bf6dbb100c | H3: =INDEX(EtiologicalAgent!$B:$B,MATCH($G3,EtiologicalAgent!$A:$A,0)) -> etiological_agent2
A4: 0195d18c-1ca6-0243-1762-326add8a5d71 | B4: case_type3 | D4: 0195d18c-1ca4-9f3c-a017-a8f11202fb1c | E4: =INDEX(Disease!$B:$B,MATCH($D4,Disease!$A:$A,0)) -> disease3 | G4: 0195d18c-1ca5-5802-0739-33f87df230d4 | H4: =INDEX(EtiologicalAgent!$B:$B,MATCH($G4,EtiologicalAgent!$A:$A,0)) -> etiological_agent3
A5: 0195d18c-1ca7-7209-a21c-556dc4fd3057 | B5: case_type4 | D5: 0195d18c-1ca4-86bf-f4e7-8c2a92ff370d | E5: =INDEX(Disease!$B:$B,MATCH($D5,Disease!$A:$A,0)) -> disease4 | G5: 0195d18c-1ca5-6d25-b2ad-a663425c8c15 | H5: =INDEX(EtiologicalAgent!$B:$B,MATCH($G5,EtiologicalAgent!$A:$A,0)) -> etiological_agent4
A6: 0195d18c-1ca7-ae33-0f89-bd1fd65da091 | B6: case_type5 | D6: 0195d18c-1ca4-6a53-af25-e4cd2ea0545a | E6: =INDEX(Disease!$B:$B,MATCH($D6,Disease!$A:$A,0)) -> disease5 | G6: 0195d18c-1ca5-49ab-b2c2-6e8556234b5c | H6: =INDEX(EtiologicalAgent!$B:$B,MATCH($G6,EtiologicalAgent!$A:$A,0)) -> etiological_agent5

Sheet CaseTypeSetCategory
A1: id | B1: name | C1: description | D1: rank | E1: purpose
A2: 0195d18c-1cb8-a47f-3df5-ebefd976f759 | B2: case_type_set_category1 | D2: 0 | E2: CONTENT

Sheet CaseTypeSet
A1: id | B1: name | C1: description | D1: case_type_set_category_id | E1: dm.case_type_set_category.name | F1: case_type_set_category | G1: rank
A2: 0195d18c-1cb8-5af5-9939-74dc8b5d3b5b | B2: case_type_set1 | D2: 0195d18c-1cb8-a47f-3df5-ebefd976f759 | E2: =INDEX(CaseTypeSetCategory!$B:$B,MATCH($D2,CaseTypeSetCategory!$A:$A,0)) -> case_type_set_category1 | G2: 0
A3: 0195d18c-1cb9-5e89-a2b4-e8204c332fd3 | B3: case_type_set2 | D3: 0195d18c-1cb8-a47f-3df5-ebefd976f759 | E3: =INDEX(CaseTypeSetCategory!$B:$B,MATCH($D3,CaseTypeSetCategory!$A:$A,0)) -> case_type_set_category1 | G3: 0
A4: 0195d18c-1cb9-7277-79d2-a96535256e4a | B4: case_type_set3 | D4: 0195d18c-1cb8-a47f-3df5-ebefd976f759 | E4: =INDEX(CaseTypeSetCategory!$B:$B,MATCH($D4,CaseTypeSetCategory!$A:$A,0)) -> case_type_set_category1 | G4: 0
A5: 0195d18c-1cba-e53b-6f58-f412630c05e2 | B5: case_type_set4 | D5: 0195d18c-1cb8-a47f-3df5-ebefd976f759 | E5: =INDEX(CaseTypeSetCategory!$B:$B,MATCH($D5,CaseTypeSetCategory!$A:$A,0)) -> case_type_set_category1 | G5: 0
A6: 0195d18c-1cba-2679-11a9-d71fc494b25a | B6: case_type_set5 | D6: 0195d18c-1cb8-a47f-3df5-ebefd976f759 | E6: =INDEX(CaseTypeSetCategory!$B:$B,MATCH($D6,CaseTypeSetCategory!$A:$A,0)) -> case_type_set_category1 | G6: 0
A7: 0195d18c-1cbb-d7b8-d852-987a801e0ad5 | B7: case_type_set1,2 | D7: 0195d18c-1cb8-a47f-3df5-ebefd976f759 | E7: =INDEX(CaseTypeSetCategory!$B:$B,MATCH($D7,CaseTypeSetCategory!$A:$A,0)) -> case_type_set_category1 | G7: 0
A8: 0195d18c-1cbb-5047-ab67-71cb2cb84047 | B8: case_type_set1,3 | D8: 0195d18c-1cb8-a47f-3df5-ebefd976f759 | E8: =INDEX(CaseTypeSetCategory!$B:$B,MATCH($D8,CaseTypeSetCategory!$A:$A,0)) -> case_type_set_category1 | G8: 0
A9: 0195d18c-1cbc-41fb-3ad7-2eed31140bd6 | B9: case_type_set1,4 | D9: 0195d18c-1cb8-a47f-3df5-ebefd976f759 | E9: =INDEX(CaseTypeSetCategory!$B:$B,MATCH($D9,CaseTypeSetCategory!$A:$A,0)) -> case_type_set_category1 | G9: 0
A10: 0195d18c-1cbc-cf9a-b28d-bd77d3b30365 | B10: case_type_set1,5 | D10: 0195d18c-1cb8-a47f-3df5-ebefd976f759 | E10: =INDEX(CaseTypeSetCategory!$B:$B,MATCH($D10,CaseTypeSetCategory!$A:$A,0)) -> case_type_set_category1 | G10: 0
A11: 0195d18c-1cbd-f948-2304-f178298dbc48 | B11: case_type_set2,3 | D11: 0195d18c-1cb8-a47f-3df5-ebefd976f759 | E11: =INDEX(CaseTypeSetCategory!$B:$B,MATCH($D11,CaseTypeSetCategory!$A:$A,0)) -> case_type_set_category1 | G11: 0
A12: 0195d18c-1cbe-394f-58eb-6d327092ba44 | B12: case_type_set2,4 | D12: 0195d18c-1cb8-a47f-3df5-ebefd976f759 | E12: =INDEX(CaseTypeSetCategory!$B:$B,MATCH($D12,CaseTypeSetCategory!$A:$A,0)) -> case_type_set_category1 | G12: 0
A13: 0195d18c-1cbe-fcd0-15db-737a74dff6fa | B13: case_type_set2,5 | D13: 0195d18c-1cb8-a47f-3df5-ebefd976f759 | E13: =INDEX(CaseTypeSetCategory!$B:$B,MATCH($D13,CaseTypeSetCategory!$A:$A,0)) -> case_type_set_category1 | G13: 0
... A16: 0195d18c-1cc0-1fae-3a05-50f42b0128fc | B16: case_type_set4,5 | D16: 0195d18c-1cb8-a47f-3df5-ebefd976f759 | E16: =INDEX(CaseTypeSetCategory!$B:$B,MATCH($D16,CaseTypeSetCategory!$A:$A,0)) -> case_type_set_category1 | G16: 0

Sheet CaseTypeSetMember
A1: id | B1: case_type_set_id | C1: dm.case_type_set.name | D1: case_type_set | E1: case_type_id | F1: dm.case_type.code | G1: case_type | H1: dm.key
A2: 0195d18c-1cb8-ac82-67f2-bc32a6368340 | B2: 0195d18c-1cb8-5af5-9939-74dc8b5d3b5b | C2: =INDEX(CaseTypeSet!$B:$B,MATCH($B2,CaseTypeSet!$A:$A,0)) -> case_type_set1 | E2: 0195d18c-1ca6-fd99-9d76-fcfa0c0cf400 | F2: =INDEX(CaseType!$B:$B,MATCH($E2,CaseType!$A:$A,0)) -> case_type1 | H2: =$B2&"|"&$E2 -> 0195d18c-1cb8-5af5-9939-74dc8b5d3b5b|0195d18c-1ca6-fd99-9d76-fcfa0c0cf400
A3: 0195d18c-1cb9-04cf-ee83-d2e14f70e6f7 | B3: 0195d18c-1cb9-5e89-a2b4-e8204c332fd3 | C3: =INDEX(CaseTypeSet!$B:$B,MATCH($B3,CaseTypeSet!$A:$A,0)) -> case_type_set2 | E3: 0195d18c-1ca6-752a-ec56-ed1b3d0cb095 | F3: =INDEX(CaseType!$B:$B,MATCH($E3,CaseType!$A:$A,0)) -> case_type2
A4: 0195d18c-1cb9-0db7-dd63-2f5c66ce2096 | B4: 0195d18c-1cb9-7277-79d2-a96535256e4a | C4: =INDEX(CaseTypeSet!$B:$B,MATCH($B4,CaseTypeSet!$A:$A,0)) -> case_type_set3 | E4: 0195d18c-1ca6-0243-1762-326add8a5d71 | F4: =INDEX(CaseType!$B:$B,MATCH($E4,CaseType!$A:$A,0)) -> case_type3
A5: 0195d18c-1cba-d75a-4f52-be8189bfd480 | B5: 0195d18c-1cba-e53b-6f58-f412630c05e2 | C5: =INDEX(CaseTypeSet!$B:$B,MATCH($B5,CaseTypeSet!$A:$A,0)) -> case_type_set4 | E5: 0195d18c-1ca7-7209-a21c-556dc4fd3057 | F5: =INDEX(CaseType!$B:$B,MATCH($E5,CaseType!$A:$A,0)) -> case_type4
A6: 0195d18c-1cba-880a-4d3d-9231b03e604d | B6: 0195d18c-1cba-2679-11a9-d71fc494b25a | C6: =INDEX(CaseTypeSet!$B:$B,MATCH($B6,CaseTypeSet!$A:$A,0)) -> case_type_set5 | E6: 0195d18c-1ca7-ae33-0f89-bd1fd65da091 | F6: =INDEX(CaseType!$B:$B,MATCH($E6,CaseType!$A:$A,0)) -> case_type5
A7: 0195d18c-1cbb-4d56-8309-26658e320187 | B7: 0195d18c-1cbb-d7b8-d852-987a801e0ad5 | C7: =INDEX(CaseTypeSet!$B:$B,MATCH($B7,CaseTypeSet!$A:$A,0)) -> case_type_set1,2 | E7: 0195d18c-1ca6-fd99-9d76-fcfa0c0cf400 | F7: =INDEX(CaseType!$B:$B,MATCH($E7,CaseType!$A:$A,0)) -> case_type1 | H7: =$B7&"|"&$E7 -> 0195d18c-1cbb-d7b8-d852-987a801e0ad5|0195d18c-1ca6-fd99-9d76-fcfa0c0cf400
A8: 0195d18c-1cbb-e8cf-b7a9-624604063760 | B8: 0195d18c-1cbb-d7b8-d852-987a801e0ad5 | C8: =INDEX(CaseTypeSet!$B:$B,MATCH($B8,CaseTypeSet!$A:$A,0)) -> case_type_set1,2 | E8: 0195d18c-1ca6-752a-ec56-ed1b3d0cb095 | F8: =INDEX(CaseType!$B:$B,MATCH($E8,CaseType!$A:$A,0)) -> case_type2
A9: 0195d18c-1cbc-34b5-25b1-15430bfc43cb | B9: 0195d18c-1cbb-5047-ab67-71cb2cb84047 | C9: =INDEX(CaseTypeSet!$B:$B,MATCH($B9,CaseTypeSet!$A:$A,0)) -> case_type_set1,3 | E9: 0195d18c-1ca6-0243-1762-326add8a5d71 | F9: =INDEX(CaseType!$B:$B,MATCH($E9,CaseType!$A:$A,0)) -> case_type3
A10: 0195d18c-1cbc-42ec-af5d-d0c541b3c295 | B10: 0195d18c-1cbb-5047-ab67-71cb2cb84047 | C10: =INDEX(CaseTypeSet!$B:$B,MATCH($B10,CaseTypeSet!$A:$A,0)) -> case_type_set1,3 | E10: 0195d18c-1ca6-fd99-9d76-fcfa0c0cf400 | F10: =INDEX(CaseType!$B:$B,MATCH($E10,CaseType!$A:$A,0)) -> case_type1 | H10: =$B10&"|"&$E10 -> 0195d18c-1cbb-5047-ab67-71cb2cb84047|0195d18c-1ca6-fd99-9d76-fcfa0c0cf400
A11: 0195d18c-1cbc-93ea-ba50-3ea9ab23cfcf | B11: 0195d18c-1cbc-41fb-3ad7-2eed31140bd6 | C11: =INDEX(CaseTypeSet!$B:$B,MATCH($B11,CaseTypeSet!$A:$A,0)) -> case_type_set1,4 | E11: 0195d18c-1ca6-fd99-9d76-fcfa0c0cf400 | F11: =INDEX(CaseType!$B:$B,MATCH($E11,CaseType!$A:$A,0)) -> case_type1 | H11: =$B11&"|"&$E11 -> 0195d18c-1cbc-41fb-3ad7-2eed31140bd6|0195d18c-1ca6-fd99-9d76-fcfa0c0cf400
A12: 0195d18c-1cbc-5d27-ec6f-91a2b6d7fba6 | B12: 0195d18c-1cbc-41fb-3ad7-2eed31140bd6 | C12: =INDEX(CaseTypeSet!$B:$B,MATCH($B12,CaseTypeSet!$A:$A,0)) -> case_type_set1,4 | E12: 0195d18c-1ca7-7209-a21c-556dc4fd3057 | F12: =INDEX(CaseType!$B:$B,MATCH($E12,CaseType!$A:$A,0)) -> case_type4
A13: 0195d18c-1cbd-afb8-4103-44bd3d6db520 | B13: 0195d18c-1cbc-cf9a-b28d-bd77d3b30365 | C13: =INDEX(CaseTypeSet!$B:$B,MATCH($B13,CaseTypeSet!$A:$A,0)) -> case_type_set1,5 | E13: 0195d18c-1ca7-ae33-0f89-bd1fd65da091 | F13: =INDEX(CaseType!$B:$B,MATCH($E13,CaseType!$A:$A,0)) -> case_type5
A14: 0195d18c-1cbd-598d-2fbc-ab1a86b38c7b | B14: 0195d18c-1cbc-cf9a-b28d-bd77d3b30365 | C14: =INDEX(CaseTypeSet!$B:$B,MATCH($B14,CaseTypeSet!$A:$A,0)) -> case_type_set1,5 | E14: 0195d18c-1ca6-fd99-9d76-fcfa0c0cf400 | F14: =INDEX(CaseType!$B:$B,MATCH($E14,CaseType!$A:$A,0)) -> case_type1 | H14: =$B14&"|"&$E14 -> 0195d18c-1cbc-cf9a-b28d-bd77d3b30365|0195d18c-1ca6-fd99-9d76-fcfa0c0cf400
A15: 0195d18c-1cbd-64ee-0053-12e519dbaea2 | B15: 0195d18c-1cbd-f948-2304-f178298dbc48 | C15: =INDEX(CaseTypeSet!$B:$B,MATCH($B15,CaseTypeSet!$A:$A,0)) -> case_type_set2,3 | E15: 0195d18c-1ca6-0243-1762-326add8a5d71 | F15: =INDEX(CaseType!$B:$B,MATCH($E15,CaseType!$A:$A,0)) -> case_type3
A16: 0195d18c-1cbd-e5e4-5e2c-49dcc5a54ec2 | B16: 0195d18c-1cbd-f948-2304-f178298dbc48 | C16: =INDEX(CaseTypeSet!$B:$B,MATCH($B16,CaseTypeSet!$A:$A,0)) -> case_type_set2,3 | E16: 0195d18c-1ca6-752a-ec56-ed1b3d0cb095 | F16: =INDEX(CaseType!$B:$B,MATCH($E16,CaseType!$A:$A,0)) -> case_type2
A17: 0195d18c-1cbe-25ec-3c13-b743a72fe44e | B17: 0195d18c-1cbe-394f-58eb-6d327092ba44 | C17: =INDEX(CaseTypeSet!$B:$B,MATCH($B17,CaseTypeSet!$A:$A,0)) -> case_type_set2,4 | E17: 0195d18c-1ca7-7209-a21c-556dc4fd3057 | F17: =INDEX(CaseType!$B:$B,MATCH($E17,CaseType!$A:$A,0)) -> case_type4
A18: 0195d18c-1cbe-ccf9-b1b3-31b52fe304c2 | B18: 0195d18c-1cbe-394f-58eb-6d327092ba44 | C18: =INDEX(CaseTypeSet!$B:$B,MATCH($B18,CaseTypeSet!$A:$A,0)) -> case_type_set2,4 | E18: 0195d18c-1ca6-752a-ec56-ed1b3d0cb095 | F18: =INDEX(CaseType!$B:$B,MATCH($E18,CaseType!$A:$A,0)) -> case_type2
A19: 0195d18c-1cbf-6781-d8e6-4821a8cca56f | B19: 0195d18c-1cbe-fcd0-15db-737a74dff6fa | C19: =INDEX(CaseTypeSet!$B:$B,MATCH($B19,CaseTypeSet!$A:$A,0)) -> case_type_set2,5 | E19: 0195d18c-1ca7-ae33-0f89-bd1fd65da091 | F19: =INDEX(CaseType!$B:$B,MATCH($E19,CaseType!$A:$A,0)) -> case_type5
A20: 0195d18c-1cbf-2af9-365a-9fcfc6325153 | B20: 0195d18c-1cbe-fcd0-15db-737a74dff6fa | C20: =INDEX(CaseTypeSet!$B:$B,MATCH($B20,CaseTypeSet!$A:$A,0)) -> case_type_set2,5 | E20: 0195d18c-1ca6-752a-ec56-ed1b3d0cb095 | F20: =INDEX(CaseType!$B:$B,MATCH($E20,CaseType!$A:$A,0)) -> case_type2
A21: 0195d18c-1cbf-cab5-f26b-de1986258d80 | B21: 0195d18c-1cbf-2a22-b845-fb9a44b67a96 | C21: =INDEX(CaseTypeSet!$B:$B,MATCH($B21,CaseTypeSet!$A:$A,0)) -> case_type_set3,4 | E21: 0195d18c-1ca6-0243-1762-326add8a5d71 | F21: =INDEX(CaseType!$B:$B,MATCH($E21,CaseType!$A:$A,0)) -> case_type3
A22: 0195d18c-1cbf-3ae8-57bc-297cbb3e0b04 | B22: 0195d18c-1cbf-2a22-b845-fb9a44b67a96 | C22: =INDEX(CaseTypeSet!$B:$B,MATCH($B22,CaseTypeSet!$A:$A,0)) -> case_type_set3,4 | E22: 0195d18c-1ca7-7209-a21c-556dc4fd3057 | F22: =INDEX(CaseType!$B:$B,MATCH($E22,CaseType!$A:$A,0)) -> case_type4
A23: 0195d18c-1cc0-5142-d6dc-6a0d5b641c6b | B23: 0195d18c-1cc0-9f98-c18d-367b41358c49 | C23: =INDEX(CaseTypeSet!$B:$B,MATCH($B23,CaseTypeSet!$A:$A,0)) -> case_type_set3,5 | E23: 0195d18c-1ca6-0243-1762-326add8a5d71 | F23: =INDEX(CaseType!$B:$B,MATCH($E23,CaseType!$A:$A,0)) -> case_type3
A24: 0195d18c-1cc0-212b-34ce-e734d4976333 | B24: 0195d18c-1cc0-9f98-c18d-367b41358c49 | C24: =INDEX(CaseTypeSet!$B:$B,MATCH($B24,CaseTypeSet!$A:$A,0)) -> case_type_set3,5 | E24: 0195d18c-1ca7-ae33-0f89-bd1fd65da091 | F24: =INDEX(CaseType!$B:$B,MATCH($E24,CaseType!$A:$A,0)) -> case_type5
A25: 0195d18c-1cc0-6108-5b6c-a68da2f4a40c | B25: 0195d18c-1cc0-1fae-3a05-50f42b0128fc | C25: =INDEX(CaseTypeSet!$B:$B,MATCH($B25,CaseTypeSet!$A:$A,0)) -> case_type_set4,5 | E25: 0195d18c-1ca7-ae33-0f89-bd1fd65da091 | F25: =INDEX(CaseType!$B:$B,MATCH($E25,CaseType!$A:$A,0)) -> case_type5
A26: 0195d18c-1cc0-3596-3a3f-e4a37028e9f8 | B26: 0195d18c-1cc0-1fae-3a05-50f42b0128fc | C26: =INDEX(CaseTypeSet!$B:$B,MATCH($B26,CaseTypeSet!$A:$A,0)) -> case_type_set4,5 | E26: 0195d18c-1ca7-7209-a21c-556dc4fd3057 | F26: =INDEX(CaseType!$B:$B,MATCH($E26,CaseType!$A:$A,0)) -> case_type4

Sheet CaseTypeCol
A1: id | B1: case_type_id | C1: case_type | D1: col_id | E1: col | F1: occurrence | G1: code | H1: rank | I1: label | J1: description | K1: min_value | L1: max_value | M1: min_datetime | N1: max_datetime | O1: min_length | P1: max_length | Q1: pattern | R1: genetic_sequence_case_type_col_id | S1: tree_algorithm_codes | T1: props
A2: 0195d18c-1caa-1722-0366-f73bd3f09ee8 | B2: 0195d18c-1ca6-fd99-9d76-fcfa0c0cf400 | D2: 0195d18c-1ca8-0d1d-088c-b8af029e62d9 | G2: case_type1_dim1_1_text | T2: {}
A3: 0195d18c-1cab-86f3-5faf-507bfa221cf6 | B3: 0195d18c-1ca6-fd99-9d76-fcfa0c0cf400 | D3: 0195d18c-1ca8-2d41-3f8a-a08c6c72781c | G3: case_type1_dim1_2_text | T3: {}
A4: 0195d18c-1cab-b4e5-a81b-6acdcc710af2 | B4: 0195d18c-1ca6-fd99-9d76-fcfa0c0cf400 | D4: 0195d18c-1ca9-5de7-c726-bbac813384cb | G4: case_type1_dim1_3_text | T4: {}
A5: 0195d18c-1cab-3208-7ccc-820a8c522208 | B5: 0195d18c-1ca6-fd99-9d76-fcfa0c0cf400 | D5: 0195d18c-1ca9-79ee-762e-93e2d841f46e | G5: case_type1_dim2_1_text | T5: {}
A6: 0195d18c-1cab-767e-81b1-986e918827fb | B6: 0195d18c-1ca6-fd99-9d76-fcfa0c0cf400 | D6: 0195d18c-1ca9-e6f0-c3d1-2695fe9f64f9 | G6: case_type1_dim2_2_text | T6: {}
A7: 0195d18c-1cab-22f7-dda1-cc74cee303ca | B7: 0195d18c-1ca6-fd99-9d76-fcfa0c0cf400 | D7: 0195d18c-1ca9-ec62-d071-2b041d96f2c7 | G7: case_type1_dim2_3_text | T7: {}
A8: 0195d18c-1cac-4ed2-2296-a46fa423ce99 | B8: 0195d18c-1ca6-fd99-9d76-fcfa0c0cf400 | D8: 0195d18c-1ca9-2301-2c4f-a4762f675f45 | G8: case_type1_dim3_1_text | T8: {}
A9: 0195d18c-1cac-9221-a9c7-72e70e09dea9 | B9: 0195d18c-1ca6-fd99-9d76-fcfa0c0cf400 | D9: 0195d18c-1caa-e67f-100d-0d313ce91422 | G9: case_type1_dim3_2_text | T9: {}
A10: 0195d18c-1cac-4d0a-db2e-5a54065df180 | B10: 0195d18c-1ca6-fd99-9d76-fcfa0c0cf400 | D10: 0195d18c-1caa-aad7-3b8b-2357d679761c | G10: case_type1_dim3_3_text | T10: {}
A11: 0195d18c-1cad-37c6-0826-9671f313fb2b | B11: 0195d18c-1ca6-752a-ec56-ed1b3d0cb095 | D11: 0195d18c-1ca8-0d1d-088c-b8af029e62d9 | G11: case_type2_dim1_1_text | T11: {}
A12: 0195d18c-1cad-5b48-8a72-25050cbf379e | B12: 0195d18c-1ca6-752a-ec56-ed1b3d0cb095 | D12: 0195d18c-1ca8-2d41-3f8a-a08c6c72781c | G12: case_type2_dim1_2_text | T12: {}
A13: 0195d18c-1cad-e18e-a87d-8af6760d00e1 | B13: 0195d18c-1ca6-752a-ec56-ed1b3d0cb095 | D13: 0195d18c-1ca9-5de7-c726-bbac813384cb | G13: case_type2_dim1_3_text | T13: {}
... A46: 0195d18c-1cb7-e7f7-a41d-bacd0f861a06 | B46: 0195d18c-1ca7-ae33-0f89-bd1fd65da091 | D46: 0195d18c-1caa-aad7-3b8b-2357d679761c | G46: case_type5_dim3_3_text | T46: {}

Sheet CaseTypeColSet
A1: id | B1: name | C1: description
A2: 0195d18c-1cc1-44c2-1d6e-874dad333458 | B2: case_type_col_set1_1_1 | C2: case_type_col_set1_1_1
A3: 0195d18c-1cc1-c475-eba4-c3df5aea8858 | B3: case_type_col_set1_1_2 | C3: case_type_col_set1_1_2
A4: 0195d18c-1cc2-37d1-f6c3-0e7c8d6b1f07 | B4: case_type_col_set1_1_3 | C4: case_type_col_set1_1_3
A5: 0195d18c-1cc2-7cf5-8b5c-03f41714d8b8 | B5: case_type_col_set1_2_1 | C5: case_type_col_set1_2_1
A6: 0195d18c-1cc2-50aa-7113-6b261eaeec7a | B6: case_type_col_set1_2_2 | C6: case_type_col_set1_2_2
A7: 0195d18c-1cc3-0cbc-2362-c1cfe3fdec5a | B7: case_type_col_set1_2_3 | C7: case_type_col_set1_2_3
A8: 0195d18c-1cc3-e9c0-5858-8bf9d9d8c36f | B8: case_type_col_set1_3_1 | C8: case_type_col_set1_3_1
A9: 0195d18c-1cc4-9f18-3767-29d288f47190 | B9: case_type_col_set1_3_2 | C9: case_type_col_set1_3_2
A10: 0195d18c-1cc5-2ea3-8102-7b410f3146c8 | B10: case_type_col_set1_3_3 | C10: case_type_col_set1_3_3
A11: 0195d18c-1cc6-a324-3f72-222014292515 | B11: case_type_col_set2_1_1 | C11: case_type_col_set2_1_1
A12: 0195d18c-1cc7-243f-f4e7-3dbdfe691c71 | B12: case_type_col_set2_1_2 | C12: case_type_col_set2_1_2
... A46: 0195d18c-1cd7-b95b-ced6-589a63e3e6eb | B46: case_type_col_set5_3_3 | C46: case_type_col_set5_3_3

Sheet CaseTypeColSetMember
A1: id | B1: case_type_col_set_id | C1: dm.case_type_col_set.code | D1: case_type_col_set | E1: case_type_col_id | F1: dm.case_type_col.code | G1: case_type_col | H1: dm.key
A2: 0195d18c-1cc1-bc3b-7023-b090ec9fde88 | B2: 0195d18c-1cc1-44c2-1d6e-874dad333458 | C2: =INDEX(CaseTypeColSet!$B:$B,MATCH($B2,CaseTypeColSet!$A:$A,0)) -> case_type_col_set1_1_1 | E2: 0195d18c-1caa-1722-0366-f73bd3f09ee8 | F2: =INDEX(CaseTypeCol!$G:$G,MATCH($E2,CaseTypeCol!$A:$A,0)) -> case_type1_dim1_1_text | H2: =$B2&"|"&$E2 -> 0195d18c-1cc1-44c2-1d6e-874dad333458|0195d18c-1caa-1722-0366-f73bd3f09ee8
A3: 0195d18c-1cc1-0f5e-c6ae-7d0853762b78 | B3: 0195d18c-1cc1-c475-eba4-c3df5aea8858 | C3: =INDEX(CaseTypeColSet!$B:$B,MATCH($B3,CaseTypeColSet!$A:$A,0)) -> case_type_col_set1_1_2 | E3: 0195d18c-1cab-86f3-5faf-507bfa221cf6 | F3: =INDEX(CaseTypeCol!$G:$G,MATCH($E3,CaseTypeCol!$A:$A,0)) -> case_type1_dim1_2_text | H3: =$B3&"|"&$E3 -> 0195d18c-1cc1-c475-eba4-c3df5aea8858|0195d18c-1cab-86f3-5faf-507bfa221cf6
A4: 0195d18c-1cc2-c1f8-0499-314e9a217619 | B4: 0195d18c-1cc2-37d1-f6c3-0e7c8d6b1f07 | C4: =INDEX(CaseTypeColSet!$B:$B,MATCH($B4,CaseTypeColSet!$A:$A,0)) -> case_type_col_set1_1_3 | E4: 0195d18c-1cab-b4e5-a81b-6acdcc710af2 | F4: =INDEX(CaseTypeCol!$G:$G,MATCH($E4,CaseTypeCol!$A:$A,0)) -> case_type1_dim1_3_text | H4: =$B4&"|"&$E4 -> 0195d18c-1cc2-37d1-f6c3-0e7c8d6b1f07|0195d18c-1cab-b4e5-a81b-6acdcc710af2
A5: 0195d18c-1cc2-1b3f-7ef2-a1a00508cf8b | B5: 0195d18c-1cc2-7cf5-8b5c-03f41714d8b8 | C5: =INDEX(CaseTypeColSet!$B:$B,MATCH($B5,CaseTypeColSet!$A:$A,0)) -> case_type_col_set1_2_1 | E5: 0195d18c-1cab-3208-7ccc-820a8c522208 | F5: =INDEX(CaseTypeCol!$G:$G,MATCH($E5,CaseTypeCol!$A:$A,0)) -> case_type1_dim2_1_text | H5: =$B5&"|"&$E5 -> 0195d18c-1cc2-7cf5-8b5c-03f41714d8b8|0195d18c-1cab-3208-7ccc-820a8c522208
A6: 0195d18c-1cc3-b4fe-f9f7-0685cbaa31bb | B6: 0195d18c-1cc2-50aa-7113-6b261eaeec7a | C6: =INDEX(CaseTypeColSet!$B:$B,MATCH($B6,CaseTypeColSet!$A:$A,0)) -> case_type_col_set1_2_2 | E6: 0195d18c-1cab-767e-81b1-986e918827fb | F6: =INDEX(CaseTypeCol!$G:$G,MATCH($E6,CaseTypeCol!$A:$A,0)) -> case_type1_dim2_2_text | H6: =$B6&"|"&$E6 -> 0195d18c-1cc2-50aa-7113-6b261eaeec7a|0195d18c-1cab-767e-81b1-986e918827fb
A7: 0195d18c-1cc3-fe61-cacc-00b203019a57 | B7: 0195d18c-1cc3-0cbc-2362-c1cfe3fdec5a | C7: =INDEX(CaseTypeColSet!$B:$B,MATCH($B7,CaseTypeColSet!$A:$A,0)) -> case_type_col_set1_2_3 | E7: 0195d18c-1cab-22f7-dda1-cc74cee303ca | F7: =INDEX(CaseTypeCol!$G:$G,MATCH($E7,CaseTypeCol!$A:$A,0)) -> case_type1_dim2_3_text | H7: =$B7&"|"&$E7 -> 0195d18c-1cc3-0cbc-2362-c1cfe3fdec5a|0195d18c-1cab-22f7-dda1-cc74cee303ca
A8: 0195d18c-1cc3-efe3-8294-1bd2eeecd725 | B8: 0195d18c-1cc3-e9c0-5858-8bf9d9d8c36f | C8: =INDEX(CaseTypeColSet!$B:$B,MATCH($B8,CaseTypeColSet!$A:$A,0)) -> case_type_col_set1_3_1 | E8: 0195d18c-1cac-4ed2-2296-a46fa423ce99 | F8: =INDEX(CaseTypeCol!$G:$G,MATCH($E8,CaseTypeCol!$A:$A,0)) -> case_type1_dim3_1_text | H8: =$B8&"|"&$E8 -> 0195d18c-1cc3-e9c0-5858-8bf9d9d8c36f|0195d18c-1cac-4ed2-2296-a46fa423ce99
A9: 0195d18c-1cc4-c572-530d-d5d4c30deb5f | B9: 0195d18c-1cc4-9f18-3767-29d288f47190 | C9: =INDEX(CaseTypeColSet!$B:$B,MATCH($B9,CaseTypeColSet!$A:$A,0)) -> case_type_col_set1_3_2 | E9: 0195d18c-1cac-9221-a9c7-72e70e09dea9 | F9: =INDEX(CaseTypeCol!$G:$G,MATCH($E9,CaseTypeCol!$A:$A,0)) -> case_type1_dim3_2_text | H9: =$B9&"|"&$E9 -> 0195d18c-1cc4-9f18-3767-29d288f47190|0195d18c-1cac-9221-a9c7-72e70e09dea9
A10: 0195d18c-1cc5-36c7-d184-b8289b270f98 | B10: 0195d18c-1cc5-2ea3-8102-7b410f3146c8 | C10: =INDEX(CaseTypeColSet!$B:$B,MATCH($B10,CaseTypeColSet!$A:$A,0)) -> case_type_col_set1_3_3 | E10: 0195d18c-1cac-4d0a-db2e-5a54065df180 | F10: =INDEX(CaseTypeCol!$G:$G,MATCH($E10,CaseTypeCol!$A:$A,0)) -> case_type1_dim3_3_text | H10: =$B10&"|"&$E10 -> 0195d18c-1cc5-2ea3-8102-7b410f3146c8|0195d18c-1cac-4d0a-db2e-5a54065df180
A11: 0195d18c-1cc6-dfd8-d42b-028bcb2eda6e | B11: 0195d18c-1cc6-a324-3f72-222014292515 | C11: =INDEX(CaseTypeColSet!$B:$B,MATCH($B11,CaseTypeColSet!$A:$A,0)) -> case_type_col_set2_1_1 | E11: 0195d18c-1cad-37c6-0826-9671f313fb2b | F11: =INDEX(CaseTypeCol!$G:$G,MATCH($E11,CaseTypeCol!$A:$A,0)) -> case_type2_dim1_1_text | H11: =$B11&"|"&$E11 -> 0195d18c-1cc6-a324-3f72-222014292515|0195d18c-1cad-37c6-0826-9671f313fb2b
A12: 0195d18c-1cc7-85ac-2749-1dcda89a900a | B12: 0195d18c-1cc7-243f-f4e7-3dbdfe691c71 | C12: =INDEX(CaseTypeColSet!$B:$B,MATCH($B12,CaseTypeColSet!$A:$A,0)) -> case_type_col_set2_1_2 | E12: 0195d18c-1cad-5b48-8a72-25050cbf379e | F12: =INDEX(CaseTypeCol!$G:$G,MATCH($E12,CaseTypeCol!$A:$A,0)) -> case_type2_dim1_2_text | H12: =$B12&"|"&$E12 -> 0195d18c-1cc7-243f-f4e7-3dbdfe691c71|0195d18c-1cad-5b48-8a72-25050cbf379e
A13: 0195d18c-1cc7-93ce-aacd-c48aa7a52deb | B13: 0195d18c-1cc7-60b4-b4e6-8ff7fabb2b09 | C13: =INDEX(CaseTypeColSet!$B:$B,MATCH($B13,CaseTypeColSet!$A:$A,0)) -> case_type_col_set2_1_3 | E13: 0195d18c-1cad-e18e-a87d-8af6760d00e1 | F13: =INDEX(CaseTypeCol!$G:$G,MATCH($E13,CaseTypeCol!$A:$A,0)) -> case_type2_dim1_3_text | H13: =$B13&"|"&$E13 -> 0195d18c-1cc7-60b4-b4e6-8ff7fabb2b09|0195d18c-1cad-e18e-a87d-8af6760d00e1
... A46: 0195d18c-1cd8-43b4-813b-bc0358a7e252 | B46: 0195d18c-1cd7-b95b-ced6-589a63e3e6eb | C46: =INDEX(CaseTypeColSet!$B:$B,MATCH($B46,CaseTypeColSet!$A:$A,0)) -> case_type_col_set5_3_3 | E46: 0195d18c-1cb7-e7f7-a41d-bacd0f861a06 | F46: =INDEX(CaseTypeCol!$G:$G,MATCH($E46,CaseTypeCol!$A:$A,0)) -> case_type5_dim3_3_text | H46: =$B46&"|"&$E46 -> 0195d18c-1cd7-b95b-ced6-589a63e3e6eb|0195d18c-1cb7-e7f7-a41d-bacd0f861a06

Sheet OrganizationAdminPolicy
A1: id | B1: organization_id | C1: dm.organization | D1: user_id | E1: dm.user | F1: is_active
A2: 0195d18c-1c94-41b6-e8f3-0f0c398955cd | B2: 018d074d-ea0c-e942-07db-a3cc0ba1d653 | C2: =VLOOKUP(B2,Organization!$A:$B,2,0) -> org1 | D2: 0195d18c-1c93-1f4b-8c40-19223d6c7a8c | E2: =VLOOKUP(D2,User!$A:$D,3,0) -> org_admin1_1@org1.org | F2: TRUE
A3: 0195d18c-1c95-decc-cac0-6dcf11e700b2 | B3: 0195d18c-1c92-0ed4-2e94-b4f66d82baf3 | C3: =VLOOKUP(B3,Organization!$A:$B,2,0) -> org2 | D3: 0195d18c-1c95-2343-576e-0c14e0a4505d | E3: =VLOOKUP(D3,User!$A:$D,3,0) -> org_admin2_1@org2.org | F3: TRUE
A4: 0195d18c-1c96-5f7f-1e03-41e6478e8a85 | B4: 0195d18c-1c92-52b3-93e0-43dc1f2aa037 | C4: =VLOOKUP(B4,Organization!$A:$B,2,0) -> org3 | D4: 0195d18c-1c96-59a8-d2a6-70a3b13175a1 | E4: =VLOOKUP(D4,User!$A:$D,3,0) -> org_admin3_1@org3.org | F4: TRUE
A5: 0195d18c-1c97-7de8-a991-dfab21b4343d | B5: 0195d18c-1c92-d419-4c71-a570f428499b | C5: =VLOOKUP(B5,Organization!$A:$B,2,0) -> org4 | D5: 0195d18c-1c96-08ed-1241-eaf327bd1ffc | E5: =VLOOKUP(D5,User!$A:$D,3,0) -> org_admin4_1@org4.org | F5: TRUE
A6: 0195d18c-1c97-accb-a8a4-395f09f0f1e0 | B6: 0195d18c-1c93-02a2-6920-7e4dbfb73ce0 | C6: =VLOOKUP(B6,Organization!$A:$B,2,0) -> org5 | D6: 0195d18c-1c97-faac-82eb-3e357979b402 | E6: =VLOOKUP(D6,User!$A:$D,3,0) -> org_admin5_1@org5.org | F6: TRUE

Sheet CaseCrudCommand
A1: index | B1: dm.is_active | C1: id | D1: user.id | E1: user.name | F1: operation | G1: is_allowed | H1: dm.organization.id | I1: dm.user.roles.is_ge_app_admin | J1: dm.organization_access_case_policy.row | K1: dm.organization_access_case_policy.case_type_set.contains_case_type | L1: dm.organization_access_case_policy.add_case | M1: dm.organization_access_case_policy.remove_case | N1: dm.user_access_case_policy.row | O1: dm.user_access_case_policy.case_type_set.contains_case_type | P1: dm.user_access_case_policy.add_case | Q1: dm.user_access_case_policy.remove_case | R1: case.id | S1: case.case_type_id | T1: dm.case.case_type.code | U1: dm.case.case_type.cols_match | V1: case.subject_id | W1: case.created_in_data_collection_id | X1: dm.case.created_in_data_collection.name | Y1: case.count | Z1: case.case_date | AA1: case.content.case_type_col_id1 | AB1: case.content.case_type_col_value1 | AC1: dm.case.content.case_type_col_code1 | AD1: dm.organization_access_case_policy.read_case_type_col_set.contains_col1 | AE1: dm.organization_access_case_policy.write_case_type_col_set.contains_col1 | AF1: dm.user_access_case_policy.read_case_type_col_set.contains_col1 | AG1: dm.user_access_case_policy.write_case_type_col_set.contains_col1 | AH1: case.content.case_type_col_id2 | AI1: case.content.case_type_col_value2 | AJ1: dm.case.content.case_type_col_code2 | AK1: dm.organization_access_case_policy.read_case_type_col_set.contains_col2 | AL1: dm.organization_access_case_policy.write_case_type_col_set.contains_col2 | AM1: dm.user_access_case_policy.read_case_type_col_set.contains_col2 | AN1: dm.user_access_case_policy.write_case_type_col_set.contains_col2 | AO1: case.content.case_type_col_id3 | AP1: case.content.case_type_col_value3 | AQ1: dm.case.content.case_type_col_code3 | AR1: dm.organization_access_case_policy.read_case_type_col_set.contains_col3 | AS1: dm.organization_access_case_policy.write_case_type_col_set.contains_col3 | AT1: dm.user_access_case_policy.read_case_type_col_set.contains_col3 | AU1: dm.user_access_case_policy.write_case_type_col_set.contains_col3
A2: 1 | B2: TRUE | C2: 0198221b-5adb-2bd2-27ee-f32693770240 | D2: 019542cc-8225-8f5d-fa30-d9c3f2629703 | E2: =INDEX(User!$D:$D,MATCH($D2,User!$A:$A,0)) -> root1_1 | F2: CREATE | G2: =IF($F2="CREATE",$I2,IF($F2="CREATE_CASES",OR($I2,AND($K2,$L2,$O2,$P2,$AE2,AG2,$AL2,$AN2,$AS2,$AU2)),"TBD")) -> TRUE | H2: =INDEX(User!$G:$G,MATCH($D2,User!$A:$A,0)) -> 018d074d-ea0c-e942-07db-a3cc0ba1d653 | I2: =INDEX(User!$M:$M,MATCH($D2,User!$A:$A,0)) -> TRUE | J2: =IF(ISNA(MATCH($H2&"|"&$W2,OrganizationAccessCasePolicy!$V:$V,0)),"",MATCH($H2&"|"&$W2,OrganizationAccessCasePolicy!$V:$V,0)) -> 2 | K2: {=IF($J2="",FALSE,NOT(ISNA(MATCH(INDIRECT("OrganizationAccessCasePolicy!D"&$J2)&"|"&$S2,CaseTypeSetMember!$H:$H,0))))} -> TRUE | L2: {=IF($J2="",FALSE,AND(INDIRECT("OrganizationAccessCasePolicy!H"&$J2),NOT(ISNA(MATCH(INDIRECT("OrganizationAccessCasePolicy!D"&$J2)&"|"&$S2,CaseTypeSetMember!$H:$H,0)))))} -> TRUE | M2: {=IF($J2="",FALSE,AND(INDIRECT("OrganizationAccessCasePolicy!I"&$J2),NOT(ISNA(MATCH(INDIRECT("OrganizationAccessCasePolicy!D"&$J2)&"|"&$S2,CaseTypeSetMember!$H:$H,0)))))} -> TRUE | N2: =IF(ISNA(MATCH($D2&"|"&$W2,UserAccessCasePolicy!$W:$W,0)),"",MATCH($D2&"|"&$W2,UserAccessCasePolicy!$W:$W,0)) | O2: {=IF($N2="",FALSE,NOT(ISNA(MATCH(INDIRECT("UserAccessCasePolicy!D"&$N2)&"|"&$S2,CaseTypeSetMember!$H:$H,0))))} -> FALSE | P2: {=IF($N2="",FALSE,AND(INDIRECT("UserAccessCasePolicy!G"&$N2),NOT(ISNA(MATCH(INDIRECT("UserAccessCasePolicy!D"&$N2)&"|"&$S2,CaseTypeSetMember!$H:$H,0)))))} -> FALSE | Q2: {=IF($N2="",FALSE,AND(INDIRECT("UserAccessCasePolicy!H"&$N2),NOT(ISNA(MATCH(INDIRECT("UserAccessCasePolicy!D"&$N2)&"|"&$S2,CaseTypeSetMember!$H:$H,0)))))} -> FALSE | R2: 0198221b-5adb-2c9d-bed2-3ec38384a0ef | S2: 0195d18c-1ca6-fd99-9d76-fcfa0c0cf400 | T2: =INDEX(CaseType!$B:$B,MATCH($S2,CaseType!$A:$A,0)) -> case_type1 | U2: =AND(IF($AA2="",TRUE,$S2=INDEX(CaseTypeCol!$B:$B,MATCH($AA2,CaseTypeCol!$A:$A,0))),IF($AH2="",TRUE,$S2=INDEX(CaseTypeCol!$B:$B,MATCH($AH2,CaseTypeCol!$A:$A,0))),IF($AO2="",TRUE,$S2=INDEX(CaseTypeCol!$B:$B,MATCH($AO2,CaseTypeCol!$A:$A,0)))) -> TRUE | W2: 0195d18c-1ca2-a23d-1f64-00271f63199c | X2: =INDEX(DataCollection!$B:$B,MATCH($W2,DataCollection!$A:$A,0)) -> data_collection1 | Z2: 36526 | AA2: 0195d18c-1caa-1722-0366-f73bd3f09ee8 | AB2: a | AC2: =IF($AA2="","",INDEX(CaseTypeCol!$G:$G,MATCH($AA2,CaseTypeCol!$A:$A,0))) -> case_type1_dim1_1_text | AD2: {=IF($AA2="",TRUE,IF($J2="",FALSE,IF(INDIRECT("OrganizationAccessCasePolicy!J"&$J2)="",FALSE,NOT(ISNA(MATCH(INDIRECT("OrganizationAccessCasePolicy!J"&$J2)&"|"&$AA2,CaseTypeColSetMember!$H:$H,0))))))} -> TRUE | AE2: {=IF($AA2="",TRUE,IF($J2="",FALSE,IF(INDIRECT("OrganizationAccessCasePolicy!L"&$J2)="",FALSE,NOT(ISNA(MATCH(INDIRECT("OrganizationAccessCasePolicy!L"&$J2)&"|"&$AA2,CaseTypeColSetMember!$H:$H,0))))))} -> TRUE | AF2: {=IF($AA2="",TRUE,IF($N2="",FALSE,IF(INDIRECT("UserAccessCasePolicy!I"&$N2)="",FALSE,NOT(ISNA(MATCH(INDIRECT("UserAccessCasePolicy!I"&$N2)&"|"&$AA2,CaseTypeColSetMember!$H:$H,0))))))} -> FALSE | AG2: {=IF($AA2="",TRUE,IF($N2="",FALSE,IF(INDIRECT("UserAccessCasePolicy!K"&$N2)="",FALSE,NOT(ISNA(MATCH(INDIRECT("UserAccessCasePolicy!K"&$N2)&"|"&$AA2,CaseTypeColSetMember!$H:$H,0))))))} -> FALSE | AJ2: =IF($AH2="","",INDEX(CaseTypeCol!$G:$G,MATCH($AH2,CaseTypeCol!$A:$A,0))) | AK2: {=IF($AH2="",TRUE,IF($J2="",FALSE,IF(INDIRECT("OrganizationAccessCasePolicy!J"&$J2)="",FALSE,NOT(ISNA(MATCH(INDIRECT("OrganizationAccessCasePolicy!J"&$J2)&"|"&$AH2,CaseTypeColSetMember!$H:$H,0))))))} -> TRUE | AL2: {=IF($AH2="",TRUE,IF($J2="",FALSE,IF(INDIRECT("OrganizationAccessCasePolicy!L"&$J2)="",FALSE,NOT(ISNA(MATCH(INDIRECT("OrganizationAccessCasePolicy!L"&$J2)&"|"&$AH2,CaseTypeColSetMember!$H:$H,0))))))} -> TRUE | AM2: {=IF($AH2="",TRUE,IF($N2="",FALSE,IF(INDIRECT("UserAccessCasePolicy!I"&$N2)="",FALSE,NOT(ISNA(MATCH(INDIRECT("UserAccessCasePolicy!I"&$N2)&"|"&$AH2,CaseTypeColSetMember!$H:$H,0))))))} -> TRUE | AN2: {=IF($AH2="",TRUE,IF($N2="",FALSE,IF(INDIRECT("UserAccessCasePolicy!K"&$N2)="",FALSE,NOT(ISNA(MATCH(INDIRECT("UserAccessCasePolicy!K"&$N2)&"|"&$AH2,CaseTypeColSetMember!$H:$H,0))))))} -> TRUE | AQ2: =IF($AO2="","",INDEX(CaseTypeCol!$G:$G,MATCH($AO2,CaseTypeCol!$A:$A,0))) | AR2: {=IF($AO2="",TRUE,IF($J2="",FALSE,IF(INDIRECT("OrganizationAccessCasePolicy!J"&$J2)="",FALSE,NOT(ISNA(MATCH(INDIRECT("OrganizationAccessCasePolicy!J"&$J2)&"|"&$AO2,CaseTypeColSetMember!$H:$H,0))))))} -> TRUE | AS2: {=IF($AO2="",TRUE,IF($J2="",FALSE,IF(INDIRECT("OrganizationAccessCasePolicy!L"&$J2)="",FALSE,NOT(ISNA(MATCH(INDIRECT("OrganizationAccessCasePolicy!L"&$J2)&"|"&$AO2,CaseTypeColSetMember!$H:$H,0))))))} -> TRUE | AT2: {=IF($AO2="",TRUE,IF($N2="",FALSE,IF(INDIRECT("UserAccessCasePolicy!I"&$N2)="",FALSE,NOT(ISNA(MATCH(INDIRECT("UserAccessCasePolicy!I"&$N2)&"|"&$AO2,CaseTypeColSetMember!$H:$H,0))))))} -> TRUE | AU2: {=IF($AO2="",TRUE,IF($N2="",FALSE,IF(INDIRECT("UserAccessCasePolicy!K"&$N2)="",FALSE,NOT(ISNA(MATCH(INDIRECT("UserAccessCasePolicy!K"&$N2)&"|"&$AO2,CaseTypeColSetMember!$H:$H,0))))))} -> TRUE
A3: 2 | B3: TRUE | C3: 0198221b-5adb-8c9b-d440-6f661d5bac2d | D3: 0195d18c-1c92-110e-81c1-75ba0fec4494 | E3: =INDEX(User!$D:$D,MATCH($D3,User!$A:$A,0)) -> app_admin1_1 | F3: CREATE | G3: =IF($F3="CREATE",$I3,IF($F3="CREATE_CASES",OR($I3,AND($K3,$L3,$O3,$P3,$AE3,AG3,$AL3,$AN3,$AS3,$AU3)),"TBD")) -> TRUE | H3: =INDEX(User!$G:$G,MATCH($D3,User!$A:$A,0)) -> 018d074d-ea0c-e942-07db-a3cc0ba1d653 | I3: =INDEX(User!$M:$M,MATCH($D3,User!$A:$A,0)) -> TRUE | J3: =IF(ISNA(MATCH($H3&"|"&$W3,OrganizationAccessCasePolicy!$V:$V,0)),"",MATCH($H3&"|"&$W3,OrganizationAccessCasePolicy!$V:$V,0)) -> 2 | K3: {=IF($J3="",FALSE,NOT(ISNA(MATCH(INDIRECT("OrganizationAccessCasePolicy!D"&$J3)&"|"&$S3,CaseTypeSetMember!$H:$H,0))))} -> TRUE | L3: {=IF($J3="",FALSE,AND(INDIRECT("OrganizationAccessCasePolicy!H"&$J3),NOT(ISNA(MATCH(INDIRECT("OrganizationAccessCasePolicy!D"&$J3)&"|"&$S3,CaseTypeSetMember!$H:$H,0)))))} -> TRUE | M3: {=IF($J3="",FALSE,AND(INDIRECT("OrganizationAccessCasePolicy!I"&$J3),NOT(ISNA(MATCH(INDIRECT("OrganizationAccessCasePolicy!D"&$J3)&"|"&$S3,CaseTypeSetMember!$H:$H,0)))))} -> TRUE | N3: =IF(ISNA(MATCH($D3&"|"&$W3,UserAccessCasePolicy!$W:$W,0)),"",MATCH($D3&"|"&$W3,UserAccessCasePolicy!$W:$W,0)) | O3: {=IF($N3="",FALSE,NOT(ISNA(MATCH(INDIRECT("UserAccessCasePolicy!D"&$N3)&"|"&$S3,CaseTypeSetMember!$H:$H,0))))} -> FALSE | P3: {=IF($N3="",FALSE,AND(INDIRECT("UserAccessCasePolicy!G"&$N3),NOT(ISNA(MATCH(INDIRECT("UserAccessCasePolicy!D"&$N3)&"|"&$S3,CaseTypeSetMember!$H:$H,0)))))} -> FALSE | Q3: {=IF($N3="",FALSE,AND(INDIRECT("UserAccessCasePolicy!H"&$N3),NOT(ISNA(MATCH(INDIRECT("UserAccessCasePolicy!D"&$N3)&"|"&$S3,CaseTypeSetMember!$H:$H,0)))))} -> FALSE | R3: 0198221b-5adb-867c-dfe6-fb216e643760 | S3: 0195d18c-1ca6-fd99-9d76-fcfa0c0cf400 | T3: =INDEX(CaseType!$B:$B,MATCH($S3,CaseType!$A:$A,0)) -> case_type1 | U3: =AND(IF($AA3="",TRUE,$S3=INDEX(CaseTypeCol!$B:$B,MATCH($AA3,CaseTypeCol!$A:$A,0))),IF($AH3="",TRUE,$S3=INDEX(CaseTypeCol!$B:$B,MATCH($AH3,CaseTypeCol!$A:$A,0))),IF($AO3="",TRUE,$S3=INDEX(CaseTypeCol!$B:$B,MATCH($AO3,CaseTypeCol!$A:$A,0)))) -> TRUE | W3: 0195d18c-1ca2-a23d-1f64-00271f63199c | X3: =INDEX(DataCollection!$B:$B,MATCH($W3,DataCollection!$A:$A,0)) -> data_collection1 | Z3: 36526 | AA3: 0195d18c-1caa-1722-0366-f73bd3f09ee8 | AB3: a | AC3: =IF($AA3="","",INDEX(CaseTypeCol!$G:$G,MATCH($AA3,CaseTypeCol!$A:$A,0))) -> case_type1_dim1_1_text | AD3: {=IF($AA3="",TRUE,IF($J3="",FALSE,IF(INDIRECT("OrganizationAccessCasePolicy!J"&$J3)="",FALSE,NOT(ISNA(MATCH(INDIRECT("OrganizationAccessCasePolicy!J"&$J3)&"|"&$AA3,CaseTypeColSetMember!$H:$H,0))))))} -> TRUE | AE3: {=IF($AA3="",TRUE,IF($J3="",FALSE,IF(INDIRECT("OrganizationAccessCasePolicy!L"&$J3)="",FALSE,NOT(ISNA(MATCH(INDIRECT("OrganizationAccessCasePolicy!L"&$J3)&"|"&$AA3,CaseTypeColSetMember!$H:$H,0))))))} -> TRUE | AF3: {=IF($AA3="",TRUE,IF($N3="",FALSE,IF(INDIRECT("UserAccessCasePolicy!I"&$N3)="",FALSE,NOT(ISNA(MATCH(INDIRECT("UserAccessCasePolicy!I"&$N3)&"|"&$AA3,CaseTypeColSetMember!$H:$H,0))))))} -> FALSE | AG3: {=IF($AA3="",TRUE,IF($N3="",FALSE,IF(INDIRECT("UserAccessCasePolicy!K"&$N3)="",FALSE,NOT(ISNA(MATCH(INDIRECT("UserAccessCasePolicy!K"&$N3)&"|"&$AA3,CaseTypeColSetMember!$H:$H,0))))))} -> FALSE | AJ3: =IF($AH3="","",INDEX(CaseTypeCol!$G:$G,MATCH($AH3,CaseTypeCol!$A:$A,0))) | AK3: {=IF($AH3="",TRUE,IF($J3="",FALSE,IF(INDIRECT("OrganizationAccessCasePolicy!J"&$J3)="",FALSE,NOT(ISNA(MATCH(INDIRECT("OrganizationAccessCasePolicy!J"&$J3)&"|"&$AH3,CaseTypeColSetMember!$H:$H,0))))))} -> TRUE | AL3: {=IF($AH3="",TRUE,IF($J3="",FALSE,IF(INDIRECT("OrganizationAccessCasePolicy!L"&$J3)="",FALSE,NOT(ISNA(MATCH(INDIRECT("OrganizationAccessCasePolicy!L"&$J3)&"|"&$AH3,CaseTypeColSetMember!$H:$H,0))))))} -> TRUE | AM3: {=IF($AH3="",TRUE,IF($N3="",FALSE,IF(INDIRECT("UserAccessCasePolicy!I"&$N3)="",FALSE,NOT(ISNA(MATCH(INDIRECT("UserAccessCasePolicy!I"&$N3)&"|"&$AH3,CaseTypeColSetMember!$H:$H,0))))))} -> TRUE | AN3: {=IF($AH3="",TRUE,IF($N3="",FALSE,IF(INDIRECT("UserAccessCasePolicy!K"&$N3)="",FALSE,NOT(ISNA(MATCH(INDIRECT("UserAccessCasePolicy!K"&$N3)&"|"&$AH3,CaseTypeColSetMember!$H:$H,0))))))} -> TRUE | AQ3: =IF($AO3="","",INDEX(CaseTypeCol!$G:$G,MATCH($AO3,CaseTypeCol!$A:$A,0))) | AR3: {=IF($AO3="",TRUE,IF($J3="",FALSE,IF(INDIRECT("OrganizationAccessCasePolicy!J"&$J3)="",FALSE,NOT(ISNA(MATCH(INDIRECT("OrganizationAccessCasePolicy!J"&$J3)&"|"&$AO3,CaseTypeColSetMember!$H:$H,0))))))} -> TRUE | AS3: {=IF($AO3="",TRUE,IF($J3="",FALSE,IF(INDIRECT("OrganizationAccessCasePolicy!L"&$J3)="",FALSE,NOT(ISNA(MATCH(INDIRECT("OrganizationAccessCasePolicy!L"&$J3)&"|"&$AO3,CaseTypeColSetMember!$H:$H,0))))))} -> TRUE | AT3: {=IF($AO3="",TRUE,IF($N3="",FALSE,IF(INDIRECT("UserAccessCasePolicy!I"&$N3)="",FALSE,NOT(ISNA(MATCH(INDIRECT("UserAccessCasePolicy!I"&$N3)&"|"&$AO3,CaseTypeColSetMember!$H:$H,0))))))} -> TRUE | AU3: {=IF($AO3="",TRUE,IF($N3="",FALSE,IF(INDIRECT("UserAccessCasePolicy!K"&$N3)="",FALSE,NOT(ISNA(MATCH(INDIRECT("UserAccessCasePolicy!K"&$N3)&"|"&$AO3,CaseTypeColSetMember!$H:$H,0))))))} -> TRUE
A4: 3 | B4: TRUE | C4: 0198221b-5adb-07fc-811a-cec040f6fed6 | D4: 0195d18c-1c93-bcbb-eea8-94332d77b172 | E4: =INDEX(User!$D:$D,MATCH($D4,User!$A:$A,0)) -> refdata_admin1_1 | F4: CREATE | G4: =IF($F4="CREATE",$I4,IF($F4="CREATE_CASES",OR($I4,AND($K4,$L4,$O4,$P4,$AE4,AG4,$AL4,$AN4,$AS4,$AU4)),"TBD")) -> FALSE | H4: =INDEX(User!$G:$G,MATCH($D4,User!$A:$A,0)) -> 018d074d-ea0c-e942-07db-a3cc0ba1d653 | I4: =INDEX(User!$M:$M,MATCH($D4,User!$A:$A,0)) -> FALSE | J4: =IF(ISNA(MATCH($H4&"|"&$W4,OrganizationAccessCasePolicy!$V:$V,0)),"",MATCH($H4&"|"&$W4,OrganizationAccessCasePolicy!$V:$V,0)) -> 2 | K4: {=IF($J4="",FALSE,NOT(ISNA(MATCH(INDIRECT("OrganizationAccessCasePolicy!D"&$J4)&"|"&$S4,CaseTypeSetMember!$H:$H,0))))} -> TRUE | L4: {=IF($J4="",FALSE,AND(INDIRECT("OrganizationAccessCasePolicy!H"&$J4),NOT(ISNA(MATCH(INDIRECT("OrganizationAccessCasePolicy!D"&$J4)&"|"&$S4,CaseTypeSetMember!$H:$H,0)))))} -> TRUE | M4: {=IF($J4="",FALSE,AND(INDIRECT("OrganizationAccessCasePolicy!I"&$J4),NOT(ISNA(MATCH(INDIRECT("OrganizationAccessCasePolicy!D"&$J4)&"|"&$S4,CaseTypeSetMember!$H:$H,0)))))} -> TRUE | N4: =IF(ISNA(MATCH($D4&"|"&$W4,UserAccessCasePolicy!$W:$W,0)),"",MATCH($D4&"|"&$W4,UserAccessCasePolicy!$W:$W,0)) | O4: {=IF($N4="",FALSE,NOT(ISNA(MATCH(INDIRECT("UserAccessCasePolicy!D"&$N4)&"|"&$S4,CaseTypeSetMember!$H:$H,0))))} -> FALSE | P4: {=IF($N4="",FALSE,AND(INDIRECT("UserAccessCasePolicy!G"&$N4),NOT(ISNA(MATCH(INDIRECT("UserAccessCasePolicy!D"&$N4)&"|"&$S4,CaseTypeSetMember!$H:$H,0)))))} -> FALSE | Q4: {=IF($N4="",FALSE,AND(INDIRECT("UserAccessCasePolicy!H"&$N4),NOT(ISNA(MATCH(INDIRECT("UserAccessCasePolicy!D"&$N4)&"|"&$S4,CaseTypeSetMember!$H:$H,0)))))} -> FALSE | R4: 0198221b-5adb-7040-eaf9-8365166dcc2d | S4: 0195d18c-1ca6-fd99-9d76-fcfa0c0cf400 | T4: =INDEX(CaseType!$B:$B,MATCH($S4,CaseType!$A:$A,0)) -> case_type1 | U4: =AND(IF($AA4="",TRUE,$S4=INDEX(CaseTypeCol!$B:$B,MATCH($AA4,CaseTypeCol!$A:$A,0))),IF($AH4="",TRUE,$S4=INDEX(CaseTypeCol!$B:$B,MATCH($AH4,CaseTypeCol!$A:$A,0))),IF($AO4="",TRUE,$S4=INDEX(CaseTypeCol!$B:$B,MATCH($AO4,CaseTypeCol!$A:$A,0)))) -> TRUE | W4: 0195d18c-1ca2-a23d-1f64-00271f63199c | X4: =INDEX(DataCollection!$B:$B,MATCH($W4,DataCollection!$A:$A,0)) -> data_collection1 | Z4: 36526 | AA4: 0195d18c-1caa-1722-0366-f73bd3f09ee8 | AB4: a | AC4: =IF($AA4="","",INDEX(CaseTypeCol!$G:$G,MATCH($AA4,CaseTypeCol!$A:$A,0))) -> case_type1_dim1_1_text | AD4: {=IF($AA4="",TRUE,IF($J4="",FALSE,IF(INDIRECT("OrganizationAccessCasePolicy!J"&$J4)="",FALSE,NOT(ISNA(MATCH(INDIRECT("OrganizationAccessCasePolicy!J"&$J4)&"|"&$AA4,CaseTypeColSetMember!$H:$H,0))))))} -> TRUE | AE4: {=IF($AA4="",TRUE,IF($J4="",FALSE,IF(INDIRECT("OrganizationAccessCasePolicy!L"&$J4)="",FALSE,NOT(ISNA(MATCH(INDIRECT("OrganizationAccessCasePolicy!L"&$J4)&"|"&$AA4,CaseTypeColSetMember!$H:$H,0))))))} -> TRUE | AF4: {=IF($AA4="",TRUE,IF($N4="",FALSE,IF(INDIRECT("UserAccessCasePolicy!I"&$N4)="",FALSE,NOT(ISNA(MATCH(INDIRECT("UserAccessCasePolicy!I"&$N4)&"|"&$AA4,CaseTypeColSetMember!$H:$H,0))))))} -> FALSE | AG4: {=IF($AA4="",TRUE,IF($N4="",FALSE,IF(INDIRECT("UserAccessCasePolicy!K"&$N4)="",FALSE,NOT(ISNA(MATCH(INDIRECT("UserAccessCasePolicy!K"&$N4)&"|"&$AA4,CaseTypeColSetMember!$H:$H,0))))))} -> FALSE | AJ4: =IF($AH4="","",INDEX(CaseTypeCol!$G:$G,MATCH($AH4,CaseTypeCol!$A:$A,0))) | AK4: {=IF($AH4="",TRUE,IF($J4="",FALSE,IF(INDIRECT("OrganizationAccessCasePolicy!J"&$J4)="",FALSE,NOT(ISNA(MATCH(INDIRECT("OrganizationAccessCasePolicy!J"&$J4)&"|"&$AH4,CaseTypeColSetMember!$H:$H,0))))))} -> TRUE | AL4: {=IF($AH4="",TRUE,IF($J4="",FALSE,IF(INDIRECT("OrganizationAccessCasePolicy!L"&$J4)="",FALSE,NOT(ISNA(MATCH(INDIRECT("OrganizationAccessCasePolicy!L"&$J4)&"|"&$AH4,CaseTypeColSetMember!$H:$H,0))))))} -> TRUE | AM4: {=IF($AH4="",TRUE,IF($N4="",FALSE,IF(INDIRECT("UserAccessCasePolicy!I"&$N4)="",FALSE,NOT(ISNA(MATCH(INDIRECT("UserAccessCasePolicy!I"&$N4)&"|"&$AH4,CaseTypeColSetMember!$H:$H,0))))))} -> TRUE | AN4: {=IF($AH4="",TRUE,IF($N4="",FALSE,IF(INDIRECT("UserAccessCasePolicy!K"&$N4)="",FALSE,NOT(ISNA(MATCH(INDIRECT("UserAccessCasePolicy!K"&$N4)&"|"&$AH4,CaseTypeColSetMember!$H:$H,0))))))} -> TRUE | AQ4: =IF($AO4="","",INDEX(CaseTypeCol!$G:$G,MATCH($AO4,CaseTypeCol!$A:$A,0))) | AR4: {=IF($AO4="",TRUE,IF($J4="",FALSE,IF(INDIRECT("OrganizationAccessCasePolicy!J"&$J4)="",FALSE,NOT(ISNA(MATCH(INDIRECT("OrganizationAccessCasePolicy!J"&$J4)&"|"&$AO4,CaseTypeColSetMember!$H:$H,0))))))} -> TRUE | AS4: {=IF($AO4="",TRUE,IF($J4="",FALSE,IF(INDIRECT("OrganizationAccessCasePolicy!L"&$J4)="",FALSE,NOT(ISNA(MATCH(INDIRECT("OrganizationAccessCasePolicy!L"&$J4)&"|"&$AO4,CaseTypeColSetMember!$H:$H,0))))))} -> TRUE | AT4: {=IF($AO4="",TRUE,IF($N4="",FALSE,IF(INDIRECT("UserAccessCasePolicy!I"&$N4)="",FALSE,NOT(ISNA(MATCH(INDIRECT("UserAccessCasePolicy!I"&$N4)&"|"&$AO4,CaseTypeColSetMember!$H:$H,0))))))} -> TRUE | AU4: {=IF($AO4="",TRUE,IF($N4="",FALSE,IF(INDIRECT("UserAccessCasePolicy!K"&$N4)="",FALSE,NOT(ISNA(MATCH(INDIRECT("UserAccessCasePolicy!K"&$N4)&"|"&$AO4,CaseTypeColSetMember!$H:$H,0))))))} -> TRUE
